Workbook

Sheet 图4 GRPO τ原始
A1: Training Steps | B1: τ = 0.5 | C1: τ = 1.5 | D1: τ = 2 | E1: τ = 2.5 (Ours) | F1: τ = 3.5 | G1: τ = 4 | I1: 图4 · π0.5 + GRPO + DVCA | M1: τ = 3.5
A2: 1 | B2: 0.3046875 | C2: 0.3203125 | D2: 0.3203125 | E2: 0.3203125 | F2: 0.3203125 | G2: 0.3203125 | I2: 原始成功率（0–1），完整记录，未平滑 | M2: 0.3203125
A3: 2 | B3: 0.359375 | C3: 0.359375 | D3: 0.34375 | E3: 0.34375 | F3: 0.3359375 | G3: 0.3359375 | I3: 图中：MA20；横轴 0–151 Training Steps | M3: 0.3359375
A4: 3 | B4: 0.3671875 | C4: 0.3828125 | D4: 0.296875 | E4: 0.375 | F4: 0.3203125 | G4: 0.375 | M4: 0.3203125
A5: 4 | B5: 0.3828125 | C5: 0.3359375 | D5: 0.359375 | E5: 0.3671875 | F5: 0.3359375 | G5: 0.3515625 | I5: τ | J5: 记录数 | K5: 步数范围 | L5: 来源 | M5: 0.3359375
A6: 5 | B6: 0.46875 | C6: 0.5546875 | D6: 0.4375 | E6: 0.4921875 | F6: 0.484375 | G6: 0.40625 | I6: 0.5 | J6: 151 | K6: 1–151 | L6: 用户更新（B列） | M6: 0.484375
A7: 6 | B7: 0.28125 | C7: 0.328125 | D7: 0.28125 | E7: 0.28125 | F7: 0.328125 | G7: 0.2734375 | I7: 1.5 | J7: 12 | K7: 1–12 | L7: 12步；图4不绘制 | M7: 0.328125
A8: 7 | B8: 0.359375 | C8: 0.4453125 | D8: 0.4921875 | E8: 0.421875 | F8: 0.375 | G8: 0.34375 | I8: 2 | J8: 166 | K8: 1–166 | L8: 用户更新（or007） | M8: 0.375
A9: 8 | B9: 0.34375 | C9: 0.359375 | D9: 0.359375 | E9: 0.3125 | F9: 0.3125 | G9: 0.2734375 | I9: 2.5 | J9: 197 | K9: 1–197 | L9: GRPO对比 MA20，L2:L198（用户提供） | M9: 0.3125
A10: 9 | B10: 0.3046875 | C10: 0.4609375 | D10: 0.484375 | E10: 0.4453125 | F10: 0.453125 | G10: 0.375 | I10: 3.5 | J10: 162 | K10: 1–162 | L10: 用户更新（ur004，M列） | M10: 0.453125
A11: 10 | B11: 0.453125 | C11: 0.484375 | D11: 0.46875 | E11: 0.3671875 | F11: 0.4375 | G11: 0.3203125 | I11: 4 | J11: 152 | K11: 1–152 | L11: 用户更新（G列） | M11: 0.4375
A12: 11 | B12: 0.4140625 | C12: 0.390625 | D12: 0.3828125 | E12: 0.328125 | F12: 0.40625 | G12: 0.3125 | M12: 0.40625
A13: 12 | B13: 0.4609375 | C13: 0.5 | D13: 0.390625 | E13: 0.4609375 | F13: 0.46875 | G13: 0.4140625 | M13: 0.46875
A14: 13 | B14: 0.484375 | D14: 0.4609375 | E14: 0.484375 | F14: 0.4765625 | G14: 0.4453125 | M14: 0.4765625
A15: 14 | B15: 0.515625 | D15: 0.3984375 | E15: 0.3671875 | F15: 0.453125 | G15: 0.3828125 | J15: TAO1.5拿掉吧；太短了 | M15: 0.453125
A16: 15 | B16: 0.390625 | D16: 0.2265625 | E16: 0.28125 | F16: 0.3828125 | G16: 0.328125 | L16: 这列右边的tao3.5是ur004机的新数据，更新变量更控制一些，用这个； | M16: 0.3828125
A17: 16 | B17: 0.390625 | D17: 0.375 | E17: 0.390625 | F17: 0.4765625 | G17: 0.3984375 | J17: tao2这列，我换新数据了，ur005机的更稳定的数据，用这个吧； | M17: 0.4765625
A18: 17 | B18: 0.359375 | D18: 0.3828125 | E18: 0.4765625 | F18: 0.3359375 | G18: 0.4765625 | J18: tao05.这条也是，我从其他机更新过来了，重新的；用吧 | M18: 0.3359375
A19: 18 | B19: 0.3515625 | D19: 0.421875 | E19: 0.453125 | F19: 0.3671875 | G19: 0.3515625 | J19: tao4也是 | M19: 0.3671875
A20: 19 | B20: 0.4140625 | D20: 0.421875 | E20: 0.46875 | F20: 0.4375 | G20: 0.3828125 | M20: 0.4375
A21: 20 | B21: 0.2890625 | D21: 0.359375 | E21: 0.3359375 | F21: 0.2734375 | G21: 0.2734375 | J21: 更新下图吧，横轴差不多目前这样，至少到150?试试看 | M21: 0.2734375
A22: 21 | B22: 0.4375 | D22: 0.5546875 | E22: 0.4140625 | F22: 0.40625 | G22: 0.4140625 | M22: 0.40625
A23: 22 | B23: 0.46875 | D23: 0.5078125 | E23: 0.484375 | F23: 0.453125 | G23: 0.3828125 | M23: 0.453125
A24: 23 | B24: 0.4296875 | D24: 0.375 | E24: 0.4296875 | F24: 0.4921875 | G24: 0.3828125 | M24: 0.4921875
A25: 24 | B25: 0.3984375 | D25: 0.3515625 | E25: 0.3515625 | F25: 0.4296875 | G25: 0.3671875 | M25: 0.4296875
A26: 25 | B26: 0.4296875 | D26: 0.3984375 | E26: 0.4765625 | F26: 0.4296875 | G26: 0.4375 | M26: 0.4296875
A27: 26 | B27: 0.4296875 | D27: 0.453125 | E27: 0.5 | F27: 0.5078125 | G27: 0.46875 | M27: 0.5078125
A28: 27 | B28: 0.4921875 | D28: 0.5625 | E28: 0.4921875 | F28: 0.6015625 | G28: 0.46875 | M28: 0.6015625
A29: 28 | B29: 0.53125 | D29: 0.5390625 | E29: 0.4609375 | F29: 0.3125 | G29: 0.4765625 | M29: 0.3125
A30: 29 | B30: 0.515625 | D30: 0.5 | E30: 0.5234375 | F30: 0.46875 | G30: 0.4609375 | M30: 0.46875
A31: 30 | B31: 0.3125 | D31: 0.34375 | E31: 0.421875 | F31: 0.40625 | G31: 0.3203125 | M31: 0.40625
A32: 31 | B32: 0.46875 | D32: 0.421875 | E32: 0.4765625 | F32: 0.4921875 | G32: 0.3828125 | M32: 0.4921875
A33: 32 | B33: 0.4453125 | D33: 0.4609375 | E33: 0.5625 | F33: 0.5234375 | G33: 0.4765625 | M33: 0.5234375
... A152: 151 | B152: 0.640625 | D152: 0.5625 | E152: 0.5625 | F152: 0.59375 | G152: 0.53125 | M152: 0.59375
A153: 152 | D153: 0.609375 | E153: 0.625 | F153: 0.59375 | G153: 0.640625 | M153: 0.59375
A154: 153 | D154: 0.5859375 | E154: 0.6015625 | F154: 0.6015625 | M154: 0.6015625
A155: 154 | D155: 0.53125 | E155: 0.671875 | F155: 0.6015625 | M155: 0.6015625
A156: 155 | D156: 0.53125 | E156: 0.53125 | F156: 0.5078125 | M156: 0.5078125
A157: 156 | D157: 0.640625 | E157: 0.59375 | F157: 0.65625 | M157: 0.65625
A158: 157 | D158: 0.6484375 | E158: 0.671875 | F158: 0.671875 | M158: 0.671875
...

Sheet 原始曲线
A1: Training round | B1: Clean BC success rate | C1: DVAC success rate | D1: RLT Clean4 success rate | E1: RLT τ2 success rate | F1: RLT Clean8 success rate
A2: 1 | B2: 0.25 | C2: 0.25 | D2: 0 | E2: 0 | F2: 0.125
A3: 2 | B3: 0.75 | C3: 0.5 | D3: 0.75 | E3: 0.25 | F3: 0.5
A4: 3 | B4: 0.5 | C4: 0.75 | D4: 0.5 | E4: 0.5 | F4: 0.25
A5: 4 | B5: 0.5 | C5: 0.5 | D5: 0 | E5: 0.25 | F5: 0.5
A6: 5 | B6: 0.5 | C6: 0.75 | D6: 0.25 | E6: 0.25 | F6: 0.25
A7: 6 | B7: 0 | C7: 0.25 | D7: 0.25 | E7: 0 | F7: 0.125
A8: 7 | B8: 0.25 | C8: 0.75 | D8: 0.25 | E8: 0.25 | F8: 0.125
A9: 8 | B9: 0.25 | C9: 0.5 | D9: 0 | E9: 0.5 | F9: 0.25
A10: 9 | B10: 0.75 | C10: 0.75 | D10: 0.5 | E10: 0.25 | F10: 0.25
A11: 10 | B11: 0.75 | C11: 0.75 | D11: 0 | E11: 0 | F11: 0.25
A12: 11 | B12: 0.25 | C12: 0.5 | D12: 0 | E12: 0.25 | F12: 0
A13: 12 | B13: 0.5 | C13: 0.75 | D13: 0.25 | E13: 0 | F13: 0.25
... A175: 174 | B175: 0.5 | C175: 1 | D175: 0.25 | E175: 0.5 | F175: 0.5
A176: 175 | B176: 0.5 | D176: 0 | E176: 0 | F176: 0.375
A177: 176 | D177: 0 | E177: 0 | F177: 0.25
A178: 177 | D178: 0.25 | E178: 0.5 | F178: 0.625
A179: 178 | D179: 0.5 | E179: 0.5 | F179: 0.125
A180: 179 | D180: 0.5 | E180: 0.5 | F180: 0.875
A181: 180 | D181: 0.75 | E181: 0.5 | F181: 0.875
A182: 181 | D182: 0 | E182: 0 | F182: 0.5
A183: 182 | D183: 0.25 | E183: 0.75 | F183: 0.625
A184: 183 | D184: 0.25 | E184: 0.5 | F184: 0.625
A185: 184 | D185: 0.25 | E185: 0.5 | F185: 0.75
A186: 185 | D186: 0.5 | E186: 0.5 | F186: 0.875
A187: 186 | D187: 0.5 | E187: 0.75 | F187: 0.75
A188: 187 | D188: 0.25 | E188: 0.5 | F188: 0.75
... A473: 472 | D473: 0.75 | E473: 1 | F473: 1
A474: 473 | D474: 1 | E474: 1
A475: 474 | D475: 0.75 | E475: 0.5
A476: 475 | D476: 1 | E476: 0.75
A477: 476 | D477: 0.75 | E477: 1
A478: 477 | D478: 0.75 | E478: 0.75
A479: 478 | D479: 1 | E479: 0.75
A480: 479 | D480: 1 | E480: 1
A481: 480 | D481: 0.75 | E481: 1
A482: 481 | D482: 0.75 | E482: 1
A483: 482 | D483: 1 | E483: 1
A484: 483 | D484: 1 | E484: 1
A485: 484 | D485: 1 | E485: 1
...

Sheet 来源
A1: 字段 | B1: Clean BC | C1: DVAC | D1: RLT Clean4 success rate | E1: RLT τ2 success rate | F1: RLT Clean8 success rate
A2: 模型 | B2: π0.5 Sidney RoboTwin | C2: π0.5 Sidney RoboTwin | D2: π0 RoboTwin + RLT | E2: π0 RoboTwin + RLT | F2: π0 RoboTwin + RLT
A3: 任务 | B3: move_pillbottle_pad | C3: move_pillbottle_pad | D3: adjust_bottle | E3: adjust_bottle | F3: adjust_bottle
A4: 实验设置 | B4: 4 rollouts / round; U5 | C4: 4 rollouts / round; U5 | D4: 4 rollouts / round | E4: 4 rollouts / round | F4: 8 rollouts / round
A5: 数据指标 | B5: env/success_once | C5: env/success_once | D5: env/success_once | E5: env/success_once | F5: env/success_once
A6: 单位 | B6: 成功率，单元格存储为 0–1 | C6: 成功率，单元格存储为 0–1 | D6: 成功率，单元格存储为 0–1 | E6: 成功率，单元格存储为 0–1 | F6: 成功率，单元格存储为 0–1
A7: 横轴 | B7: 完成训练轮次（Training round） | C7: 完成训练轮次（Training round） | D7: 完成训练轮次（Training round） | E7: 完成训练轮次（Training round） | F7: 完成训练轮次（Training round）
A8: 完整原始范围 | B8: R1–175 | C8: R1–174 | D8: R1–800 | E8: R1–695 | F8: R1–472
A9: 原始观测数 | B9: 175 | C9: 174 | D9: 800 | E9: 695 | F9: 472
A10: TensorBoard 范围 | B10: R1–174，共 174 个点 | C10: R1–174，共 174 个点 | D10: R1–800，共 800 个点 | E10: R1–695，共 695 个点 | F10: R1–472，共 472 个点
A11: 日志补充 | B11: R175 = 50%，取自 Environment success_once | C11: R175 留空，已记录至 R174 | D11: 旧段 R1–525 + 续训 R526–800 | E11: 逐轮 TensorBoard 原值 | F11: 旧段 R1–350 + 续训 R351–472
A12: 原始数据文件 | B12: live_snapshot.json；clean_resume_metrics.log | C12: live_snapshot.json；new_resume_metrics.log | D12: remote_curves.json | E12: remote_curves.json | F12: remote_curves.json + remote_clean8_old.json
A13: 本地来源目录 | B13: drawio/资料/2026-09-12/bc/ | C13: drawio/资料/2026-09-12/bc/ | D13: 本轮曲线来源归档 | E13: 本轮曲线来源归档 | F13: 本轮曲线来源归档
A14: 来源快照时间 | B14: 46277.323 | C14: 46277.323 | D14: 2026-09-17T13:04:00.216418 UTC | E14: 2026-09-17T13:04:00.216418 UTC | F14: 2026-09-17T13:04:00.216418 UTC
A15: 原始实验 | B15: pi05-pillbottle-bc4x1-b1024-u5-m10-seed42-eval8x4-gpu6-formal100-20260908-v1 | C15: pi05-bc-dvac-new-4u5-len3-a1x1-gpu6-formal100-20260908-v1 | D15: current-single-gpu-clean-half4env-fresh600-phys7-20260914-v1 | E15: current-single-gpu-dvac-exp-t2-half4env-fresh800-phys7-20260916-v1 | F15: current-single-gpu-control-phys6-fresh600-20260912-v1
A16: 续训实验 | B16: pi05-bc-clean-4u5-gpu6-resume100to200-20260911-v1 | C16: pi05-bc-new-4u5-gpu7-resume100to200-20260911-v1 | D16: current-single-gpu-clean-half4env-resume525to800-phys6-20260917-v1 | E16: 无续训 | F16: current-single-gpu-clean-resume350to600-phys7-20260914-v1
A17: 绘图显示 | B17: R1–130；MA30，min_periods=1 | C17: R1–130；MA30，min_periods=1 | D17: 学生开始 R154；训练轮次图 MA30；采样数图固定 120 条轨迹窗口 | E17: 学生开始 R153；训练轮次图 MA30；采样数图固定 120 条轨迹窗口 | F17: 学生开始 R155；训练轮次图 MA30；采样数图固定 120 条轨迹窗口
A18: 原始表处理 | B18: 保留每轮原值 | C18: 保留每轮原值 | D18: 保留全部原始轮次；只在绘图时裁掉学生执行前阶段 | E18: 保留全部原始轮次；只在绘图时裁掉学生执行前阶段 | F18: 保留全部原始轮次；只在绘图时裁掉学生执行前阶段
A19: 续训边界 | B19: R101 接续；采集随机流和环境游标重置 | C19: R101 接续；采集随机流和环境游标重置 | D19: R525 续训；旧分叉尾部舍弃 | E19: 从头训练 | F19: R350 续训；旧分叉尾部舍弃
A20: 过滤或加权设置 | B20: 关闭 | C20: ≤3 chunks | D20: DVCA 关闭 | E20: DVCA τ=2 | F20: DVCA 关闭
A21: 快照 SHA-256 | B21: 2d336ce6c0877e5f158ef848287f4ec106db02e30ada20720440ea16dfca69ab | C21: 2d336ce6c0877e5f158ef848287f4ec106db02e30ada20720440ea16dfca69ab | D21: ce43e2ccddc5672ab3b2fb1761f1114f484c6e87f89c4033bb77937c3e5f3197 | E21: ce43e2ccddc5672ab3b2fb1761f1114f484c6e87f89c4033bb77937c3e5f3197 | F21: a7eec527a642313321643c9146c73611b132410ebe68ce3bb5e1511ae69e6f2d
A22: 续训日志 / 数据依据 | B22: 81eeafca818bb621194278f91175c2c9d4eb858f7c591a5cf01f129922c62ccd | C22: b2a07202beea03512a3a1cd74b672f112b37c542c0db25c3c4fcc029a5fbd398 | D22: TensorBoard 原始标量；step+1 对应训练轮次 | E22: TensorBoard 原始标量；step+1 对应训练轮次 | F22: TensorBoard 原始标量；step+1 对应训练轮次

Sheet π0.5 RLT 0920
A1: Global Round | B1: Clean Success | C1: DVCA Success | D1: Clean Student Step | E1: DVCA Student Step | F1: Clean MA5 | G1: DVCA MA5 | H1: Clean MA10 | I1: DVCA MA10 | J1: Clean MA15 | K1: DVCA MA15 | L1: Clean MA20 | M1: DVCA MA20 | N1: Clean MA25 | O1: DVCA MA25 | P1: Clean MA30 | Q1: DVCA MA30 | R1: Clean MA40 | S1: DVCA MA40 | T1: Clean MA50 | U1: DVCA MA50 | W1: Source | X1: Value
A2: 1 | B2: 0 | C2: 0.25 | D2: =IF(A2>=$X$2,A2-$X$2+1,"") | E2: =IF(A2>=$X$3,A2-$X$3+1,"") | F2: =AVERAGE(B2:B2) -> 0 | G2: =AVERAGE(C2:C2) -> 0.25 | H2: =AVERAGE(B2:B2) -> 0 | I2: =AVERAGE(C2:C2) -> 0.25 | J2: =AVERAGE(B2:B2) -> 0 | K2: =AVERAGE(C2:C2) -> 0.25 | L2: =AVERAGE(B2:B2) -> 0 | M2: =AVERAGE(C2:C2) -> 0.25 | N2: =AVERAGE(B2:B2) -> 0 | O2: =AVERAGE(C2:C2) -> 0.25 | P2: =AVERAGE(B2:B2) -> 0 | Q2: =AVERAGE(C2:C2) -> 0.25 | R2: =AVERAGE(B2:B2) -> 0 | S2: =AVERAGE(C2:C2) -> 0.25 | T2: =AVERAGE(B2:B2) -> 0 | U2: =AVERAGE(C2:C2) -> 0.25 | W2: Clean start | X2: 145
A3: 2 | B3: 0 | C3: 0 | D3: =IF(A3>=$X$2,A3-$X$2+1,"") | E3: =IF(A3>=$X$3,A3-$X$3+1,"") | F3: =AVERAGE(B2:B3) -> 0 | G3: =AVERAGE(C2:C3) -> 0.125 | H3: =AVERAGE(B2:B3) -> 0 | I3: =AVERAGE(C2:C3) -> 0.125 | J3: =AVERAGE(B2:B3) -> 0 | K3: =AVERAGE(C2:C3) -> 0.125 | L3: =AVERAGE(B2:B3) -> 0 | M3: =AVERAGE(C2:C3) -> 0.125 | N3: =AVERAGE(B2:B3) -> 0 | O3: =AVERAGE(C2:C3) -> 0.125 | P3: =AVERAGE(B2:B3) -> 0 | Q3: =AVERAGE(C2:C3) -> 0.125 | R3: =AVERAGE(B2:B3) -> 0 | S3: =AVERAGE(C2:C3) -> 0.125 | T3: =AVERAGE(B2:B3) -> 0 | U3: =AVERAGE(C2:C3) -> 0.125 | W3: DVCA start | X3: 146
A4: 3 | B4: 0.25 | C4: 0 | D4: =IF(A4>=$X$2,A4-$X$2+1,"") | E4: =IF(A4>=$X$3,A4-$X$3+1,"") | F4: =AVERAGE(B2:B4) -> 0.083333333 | G4: =AVERAGE(C2:C4) -> 0.083333333 | H4: =AVERAGE(B2:B4) -> 0.083333333 | I4: =AVERAGE(C2:C4) -> 0.083333333 | J4: =AVERAGE(B2:B4) -> 0.083333333 | K4: =AVERAGE(C2:C4) -> 0.083333333 | L4: =AVERAGE(B2:B4) -> 0.083333333 | M4: =AVERAGE(C2:C4) -> 0.083333333 | N4: =AVERAGE(B2:B4) -> 0.083333333 | O4: =AVERAGE(C2:C4) -> 0.083333333 | P4: =AVERAGE(B2:B4) -> 0.083333333 | Q4: =AVERAGE(C2:C4) -> 0.083333333 | R4: =AVERAGE(B2:B4) -> 0.083333333 | S4: =AVERAGE(C2:C4) -> 0.083333333 | T4: =AVERAGE(B2:B4) -> 0.083333333 | U4: =AVERAGE(C2:C4) -> 0.083333333 | W4: Episodes / round | X4: 4
A5: 4 | B5: 0 | C5: 0.25 | D5: =IF(A5>=$X$2,A5-$X$2+1,"") | E5: =IF(A5>=$X$3,A5-$X$3+1,"") | F5: =AVERAGE(B2:B5) -> 0.0625 | G5: =AVERAGE(C2:C5) -> 0.125 | H5: =AVERAGE(B2:B5) -> 0.0625 | I5: =AVERAGE(C2:C5) -> 0.125 | J5: =AVERAGE(B2:B5) -> 0.0625 | K5: =AVERAGE(C2:C5) -> 0.125 | L5: =AVERAGE(B2:B5) -> 0.0625 | M5: =AVERAGE(C2:C5) -> 0.125 | N5: =AVERAGE(B2:B5) -> 0.0625 | O5: =AVERAGE(C2:C5) -> 0.125 | P5: =AVERAGE(B2:B5) -> 0.0625 | Q5: =AVERAGE(C2:C5) -> 0.125 | R5: =AVERAGE(B2:B5) -> 0.0625 | S5: =AVERAGE(C2:C5) -> 0.125 | T5: =AVERAGE(B2:B5) -> 0.0625 | U5: =AVERAGE(C2:C5) -> 0.125 | W5: Retrieved | X5: 2026-09-20T08:12:11.889291
A6: 5 | B6: 0 | C6: 0 | D6: =IF(A6>=$X$2,A6-$X$2+1,"") | E6: =IF(A6>=$X$3,A6-$X$3+1,"") | F6: =AVERAGE(B2:B6) -> 0.05 | G6: =AVERAGE(C2:C6) -> 0.1 | H6: =AVERAGE(B2:B6) -> 0.05 | I6: =AVERAGE(C2:C6) -> 0.1 | J6: =AVERAGE(B2:B6) -> 0.05 | K6: =AVERAGE(C2:C6) -> 0.1 | L6: =AVERAGE(B2:B6) -> 0.05 | M6: =AVERAGE(C2:C6) -> 0.1 | N6: =AVERAGE(B2:B6) -> 0.05 | O6: =AVERAGE(C2:C6) -> 0.1 | P6: =AVERAGE(B2:B6) -> 0.05 | Q6: =AVERAGE(C2:C6) -> 0.1 | R6: =AVERAGE(B2:B6) -> 0.05 | S6: =AVERAGE(C2:C6) -> 0.1 | T6: =AVERAGE(B2:B6) -> 0.05 | U6: =AVERAGE(C2:C6) -> 0.1 | W6: Clean source | X6: /data/chenyiteng/results/rlinf-rlt/pi05-rlt-clean-clean4-800-20260919-v1
A7: 6 | B7: 0 | C7: 0 | D7: =IF(A7>=$X$2,A7-$X$2+1,"") | E7: =IF(A7>=$X$3,A7-$X$3+1,"") | F7: =AVERAGE(B3:B7) -> 0.05 | G7: =AVERAGE(C3:C7) -> 0.05 | H7: =AVERAGE(B2:B7) -> 0.041666667 | I7: =AVERAGE(C2:C7) -> 0.083333333 | J7: =AVERAGE(B2:B7) -> 0.041666667 | K7: =AVERAGE(C2:C7) -> 0.083333333 | L7: =AVERAGE(B2:B7) -> 0.041666667 | M7: =AVERAGE(C2:C7) -> 0.083333333 | N7: =AVERAGE(B2:B7) -> 0.041666667 | O7: =AVERAGE(C2:C7) -> 0.083333333 | P7: =AVERAGE(B2:B7) -> 0.041666667 | Q7: =AVERAGE(C2:C7) -> 0.083333333 | R7: =AVERAGE(B2:B7) -> 0.041666667 | S7: =AVERAGE(C2:C7) -> 0.083333333 | T7: =AVERAGE(B2:B7) -> 0.041666667 | U7: =AVERAGE(C2:C7) -> 0.083333333 | W7: DVCA source | X7: /data/chenyiteng/results/rlinf-rlt/pi05-rlt-combo-clean4-800-20260919-v1
A8: 7 | B8: 0 | C8: 0 | D8: =IF(A8>=$X$2,A8-$X$2+1,"") | E8: =IF(A8>=$X$3,A8-$X$3+1,"") | F8: =AVERAGE(B4:B8) -> 0.05 | G8: =AVERAGE(C4:C8) -> 0.05 | H8: =AVERAGE(B2:B8) -> 0.035714286 | I8: =AVERAGE(C2:C8) -> 0.071428571 | J8: =AVERAGE(B2:B8) -> 0.035714286 | K8: =AVERAGE(C2:C8) -> 0.071428571 | L8: =AVERAGE(B2:B8) -> 0.035714286 | M8: =AVERAGE(C2:C8) -> 0.071428571 | N8: =AVERAGE(B2:B8) -> 0.035714286 | O8: =AVERAGE(C2:C8) -> 0.071428571 | P8: =AVERAGE(B2:B8) -> 0.035714286 | Q8: =AVERAGE(C2:C8) -> 0.071428571 | R8: =AVERAGE(B2:B8) -> 0.035714286 | S8: =AVERAGE(C2:C8) -> 0.071428571 | T8: =AVERAGE(B2:B8) -> 0.035714286 | U8: =AVERAGE(C2:C8) -> 0.071428571
A9: 8 | B9: 0 | C9: 0.75 | D9: =IF(A9>=$X$2,A9-$X$2+1,"") | E9: =IF(A9>=$X$3,A9-$X$3+1,"") | F9: =AVERAGE(B5:B9) -> 0 | G9: =AVERAGE(C5:C9) -> 0.2 | H9: =AVERAGE(B2:B9) -> 0.03125 | I9: =AVERAGE(C2:C9) -> 0.15625 | J9: =AVERAGE(B2:B9) -> 0.03125 | K9: =AVERAGE(C2:C9) -> 0.15625 | L9: =AVERAGE(B2:B9) -> 0.03125 | M9: =AVERAGE(C2:C9) -> 0.15625 | N9: =AVERAGE(B2:B9) -> 0.03125 | O9: =AVERAGE(C2:C9) -> 0.15625 | P9: =AVERAGE(B2:B9) -> 0.03125 | Q9: =AVERAGE(C2:C9) -> 0.15625 | R9: =AVERAGE(B2:B9) -> 0.03125 | S9: =AVERAGE(C2:C9) -> 0.15625 | T9: =AVERAGE(B2:B9) -> 0.03125 | U9: =AVERAGE(C2:C9) -> 0.15625 | W9: Trailing mean on full history; min_periods=1; display from first actor_switch_rate > 0.
A10: 9 | B10: 0 | C10: 0 | D10: =IF(A10>=$X$2,A10-$X$2+1,"") | E10: =IF(A10>=$X$3,A10-$X$3+1,"") | F10: =AVERAGE(B6:B10) -> 0 | G10: =AVERAGE(C6:C10) -> 0.15 | H10: =AVERAGE(B2:B10) -> 0.027777778 | I10: =AVERAGE(C2:C10) -> 0.13888889 | J10: =AVERAGE(B2:B10) -> 0.027777778 | K10: =AVERAGE(C2:C10) -> 0.13888889 | L10: =AVERAGE(B2:B10) -> 0.027777778 | M10: =AVERAGE(C2:C10) -> 0.13888889 | N10: =AVERAGE(B2:B10) -> 0.027777778 | O10: =AVERAGE(C2:C10) -> 0.13888889 | P10: =AVERAGE(B2:B10) -> 0.027777778 | Q10: =AVERAGE(C2:C10) -> 0.13888889 | R10: =AVERAGE(B2:B10) -> 0.027777778 | S10: =AVERAGE(C2:C10) -> 0.13888889 | T10: =AVERAGE(B2:B10) -> 0.027777778 | U10: =AVERAGE(C2:C10) -> 0.13888889
A11: 10 | B11: 0 | C11: 0 | D11: =IF(A11>=$X$2,A11-$X$2+1,"") | E11: =IF(A11>=$X$3,A11-$X$3+1,"") | F11: =AVERAGE(B7:B11) -> 0 | G11: =AVERAGE(C7:C11) -> 0.15 | H11: =AVERAGE(B2:B11) -> 0.025 | I11: =AVERAGE(C2:C11) -> 0.125 | J11: =AVERAGE(B2:B11) -> 0.025 | K11: =AVERAGE(C2:C11) -> 0.125 | L11: =AVERAGE(B2:B11) -> 0.025 | M11: =AVERAGE(C2:C11) -> 0.125 | N11: =AVERAGE(B2:B11) -> 0.025 | O11: =AVERAGE(C2:C11) -> 0.125 | P11: =AVERAGE(B2:B11) -> 0.025 | Q11: =AVERAGE(C2:C11) -> 0.125 | R11: =AVERAGE(B2:B11) -> 0.025 | S11: =AVERAGE(C2:C11) -> 0.125 | T11: =AVERAGE(B2:B11) -> 0.025 | U11: =AVERAGE(C2:C11) -> 0.125
A12: 11 | B12: 0 | C12: 0 | D12: =IF(A12>=$X$2,A12-$X$2+1,"") | E12: =IF(A12>=$X$3,A12-$X$3+1,"") | F12: =AVERAGE(B8:B12) -> 0 | G12: =AVERAGE(C8:C12) -> 0.15 | H12: =AVERAGE(B3:B12) -> 0.025 | I12: =AVERAGE(C3:C12) -> 0.1 | J12: =AVERAGE(B2:B12) -> 0.022727273 | K12: =AVERAGE(C2:C12) -> 0.11363636 | L12: =AVERAGE(B2:B12) -> 0.022727273 | M12: =AVERAGE(C2:C12) -> 0.11363636 | N12: =AVERAGE(B2:B12) -> 0.022727273 | O12: =AVERAGE(C2:C12) -> 0.11363636 | P12: =AVERAGE(B2:B12) -> 0.022727273 | Q12: =AVERAGE(C2:C12) -> 0.11363636 | R12: =AVERAGE(B2:B12) -> 0.022727273 | S12: =AVERAGE(C2:C12) -> 0.11363636 | T12: =AVERAGE(B2:B12) -> 0.022727273 | U12: =AVERAGE(C2:C12) -> 0.11363636
A13: 12 | B13: 0 | C13: 0 | D13: =IF(A13>=$X$2,A13-$X$2+1,"") | E13: =IF(A13>=$X$3,A13-$X$3+1,"") | F13: =AVERAGE(B9:B13) -> 0 | G13: =AVERAGE(C9:C13) -> 0.15 | H13: =AVERAGE(B4:B13) -> 0.025 | I13: =AVERAGE(C4:C13) -> 0.1 | J13: =AVERAGE(B2:B13) -> 0.020833333 | K13: =AVERAGE(C2:C13) -> 0.10416667 | L13: =AVERAGE(B2:B13) -> 0.020833333 | M13: =AVERAGE(C2:C13) -> 0.10416667 | N13: =AVERAGE(B2:B13) -> 0.020833333 | O13: =AVERAGE(C2:C13) -> 0.10416667 | P13: =AVERAGE(B2:B13) -> 0.020833333 | Q13: =AVERAGE(C2:C13) -> 0.10416667 | R13: =AVERAGE(B2:B13) -> 0.020833333 | S13: =AVERAGE(C2:C13) -> 0.10416667 | T13: =AVERAGE(B2:B13) -> 0.020833333 | U13: =AVERAGE(C2:C13) -> 0.10416667
A14: 13 | B14: 0.25 | C14: 0 | D14: =IF(A14>=$X$2,A14-$X$2+1,"") | E14: =IF(A14>=$X$3,A14-$X$3+1,"") | F14: =AVERAGE(B10:B14) -> 0.05 | G14: =AVERAGE(C10:C14) -> 0 | H14: =AVERAGE(B5:B14) -> 0.025 | I14: =AVERAGE(C5:C14) -> 0.1 | J14: =AVERAGE(B2:B14) -> 0.038461538 | K14: =AVERAGE(C2:C14) -> 0.096153846 | L14: =AVERAGE(B2:B14) -> 0.038461538 | M14: =AVERAGE(C2:C14) -> 0.096153846 | N14: =AVERAGE(B2:B14) -> 0.038461538 | O14: =AVERAGE(C2:C14) -> 0.096153846 | P14: =AVERAGE(B2:B14) -> 0.038461538 | Q14: =AVERAGE(C2:C14) -> 0.096153846 | R14: =AVERAGE(B2:B14) -> 0.038461538 | S14: =AVERAGE(C2:C14) -> 0.096153846 | T14: =AVERAGE(B2:B14) -> 0.038461538 | U14: =AVERAGE(C2:C14) -> 0.096153846
A15: 14 | B15: 0 | C15: 0 | D15: =IF(A15>=$X$2,A15-$X$2+1,"") | E15: =IF(A15>=$X$3,A15-$X$3+1,"") | F15: =AVERAGE(B11:B15) -> 0.05 | G15: =AVERAGE(C11:C15) -> 0 | H15: =AVERAGE(B6:B15) -> 0.025 | I15: =AVERAGE(C6:C15) -> 0.075 | J15: =AVERAGE(B2:B15) -> 0.035714286 | K15: =AVERAGE(C2:C15) -> 0.089285714 | L15: =AVERAGE(B2:B15) -> 0.035714286 | M15: =AVERAGE(C2:C15) -> 0.089285714 | N15: =AVERAGE(B2:B15) -> 0.035714286 | O15: =AVERAGE(C2:C15) -> 0.089285714 | P15: =AVERAGE(B2:B15) -> 0.035714286 | Q15: =AVERAGE(C2:C15) -> 0.089285714 | R15: =AVERAGE(B2:B15) -> 0.035714286 | S15: =AVERAGE(C2:C15) -> 0.089285714 | T15: =AVERAGE(B2:B15) -> 0.035714286 | U15: =AVERAGE(C2:C15) -> 0.089285714
A16: 15 | B16: 0 | C16: 0.5 | D16: =IF(A16>=$X$2,A16-$X$2+1,"") | E16: =IF(A16>=$X$3,A16-$X$3+1,"") | F16: =AVERAGE(B12:B16) -> 0.05 | G16: =AVERAGE(C12:C16) -> 0.1 | H16: =AVERAGE(B7:B16) -> 0.025 | I16: =AVERAGE(C7:C16) -> 0.125 | J16: =AVERAGE(B2:B16) -> 0.033333333 | K16: =AVERAGE(C2:C16) -> 0.11666667 | L16: =AVERAGE(B2:B16) -> 0.033333333 | M16: =AVERAGE(C2:C16) -> 0.11666667 | N16: =AVERAGE(B2:B16) -> 0.033333333 | O16: =AVERAGE(C2:C16) -> 0.11666667 | P16: =AVERAGE(B2:B16) -> 0.033333333 | Q16: =AVERAGE(C2:C16) -> 0.11666667 | R16: =AVERAGE(B2:B16) -> 0.033333333 | S16: =AVERAGE(C2:C16) -> 0.11666667 | T16: =AVERAGE(B2:B16) -> 0.033333333 | U16: =AVERAGE(C2:C16) -> 0.11666667
A17: 16 | B17: 0 | C17: 0 | D17: =IF(A17>=$X$2,A17-$X$2+1,"") | E17: =IF(A17>=$X$3,A17-$X$3+1,"") | F17: =AVERAGE(B13:B17) -> 0.05 | G17: =AVERAGE(C13:C17) -> 0.1 | H17: =AVERAGE(B8:B17) -> 0.025 | I17: =AVERAGE(C8:C17) -> 0.125 | J17: =AVERAGE(B3:B17) -> 0.033333333 | K17: =AVERAGE(C3:C17) -> 0.1 | L17: =AVERAGE(B2:B17) -> 0.03125 | M17: =AVERAGE(C2:C17) -> 0.109375 | N17: =AVERAGE(B2:B17) -> 0.03125 | O17: =AVERAGE(C2:C17) -> 0.109375 | P17: =AVERAGE(B2:B17) -> 0.03125 | Q17: =AVERAGE(C2:C17) -> 0.109375 | R17: =AVERAGE(B2:B17) -> 0.03125 | S17: =AVERAGE(C2:C17) -> 0.109375 | T17: =AVERAGE(B2:B17) -> 0.03125 | U17: =AVERAGE(C2:C17) -> 0.109375
A18: 17 | B18: 0.5 | C18: 0 | D18: =IF(A18>=$X$2,A18-$X$2+1,"") | E18: =IF(A18>=$X$3,A18-$X$3+1,"") | F18: =AVERAGE(B14:B18) -> 0.15 | G18: =AVERAGE(C14:C18) -> 0.1 | H18: =AVERAGE(B9:B18) -> 0.075 | I18: =AVERAGE(C9:C18) -> 0.125 | J18: =AVERAGE(B4:B18) -> 0.066666667 | K18: =AVERAGE(C4:C18) -> 0.1 | L18: =AVERAGE(B2:B18) -> 0.058823529 | M18: =AVERAGE(C2:C18) -> 0.10294118 | N18: =AVERAGE(B2:B18) -> 0.058823529 | O18: =AVERAGE(C2:C18) -> 0.10294118 | P18: =AVERAGE(B2:B18) -> 0.058823529 | Q18: =AVERAGE(C2:C18) -> 0.10294118 | R18: =AVERAGE(B2:B18) -> 0.058823529 | S18: =AVERAGE(C2:C18) -> 0.10294118 | T18: =AVERAGE(B2:B18) -> 0.058823529 | U18: =AVERAGE(C2:C18) -> 0.10294118
A19: 18 | B19: 0 | C19: 0.25 | D19: =IF(A19>=$X$2,A19-$X$2+1,"") | E19: =IF(A19>=$X$3,A19-$X$3+1,"") | F19: =AVERAGE(B15:B19) -> 0.1 | G19: =AVERAGE(C15:C19) -> 0.15 | H19: =AVERAGE(B10:B19) -> 0.075 | I19: =AVERAGE(C10:C19) -> 0.075 | J19: =AVERAGE(B5:B19) -> 0.05 | K19: =AVERAGE(C5:C19) -> 0.11666667 | L19: =AVERAGE(B2:B19) -> 0.055555556 | M19: =AVERAGE(C2:C19) -> 0.11111111 | N19: =AVERAGE(B2:B19) -> 0.055555556 | O19: =AVERAGE(C2:C19) -> 0.11111111 | P19: =AVERAGE(B2:B19) -> 0.055555556 | Q19: =AVERAGE(C2:C19) -> 0.11111111 | R19: =AVERAGE(B2:B19) -> 0.055555556 | S19: =AVERAGE(C2:C19) -> 0.11111111 | T19: =AVERAGE(B2:B19) -> 0.055555556 | U19: =AVERAGE(C2:C19) -> 0.11111111
A20: 19 | B20: 0.25 | C20: 0 | D20: =IF(A20>=$X$2,A20-$X$2+1,"") | E20: =IF(A20>=$X$3,A20-$X$3+1,"") | F20: =AVERAGE(B16:B20) -> 0.15 | G20: =AVERAGE(C16:C20) -> 0.15 | H20: =AVERAGE(B11:B20) -> 0.1 | I20: =AVERAGE(C11:C20) -> 0.075 | J20: =AVERAGE(B6:B20) -> 0.066666667 | K20: =AVERAGE(C6:C20) -> 0.1 | L20: =AVERAGE(B2:B20) -> 0.065789474 | M20: =AVERAGE(C2:C20) -> 0.10526316 | N20: =AVERAGE(B2:B20) -> 0.065789474 | O20: =AVERAGE(C2:C20) -> 0.10526316 | P20: =AVERAGE(B2:B20) -> 0.065789474 | Q20: =AVERAGE(C2:C20) -> 0.10526316 | R20: =AVERAGE(B2:B20) -> 0.065789474 | S20: =AVERAGE(C2:C20) -> 0.10526316 | T20: =AVERAGE(B2:B20) -> 0.065789474 | U20: =AVERAGE(C2:C20) -> 0.10526316
A21: 20 | B21: 0.5 | C21: 0 | D21: =IF(A21>=$X$2,A21-$X$2+1,"") | E21: =IF(A21>=$X$3,A21-$X$3+1,"") | F21: =AVERAGE(B17:B21) -> 0.25 | G21: =AVERAGE(C17:C21) -> 0.05 | H21: =AVERAGE(B12:B21) -> 0.15 | I21: =AVERAGE(C12:C21) -> 0.075 | J21: =AVERAGE(B7:B21) -> 0.1 | K21: =AVERAGE(C7:C21) -> 0.1 | L21: =AVERAGE(B2:B21) -> 0.0875 | M21: =AVERAGE(C2:C21) -> 0.1 | N21: =AVERAGE(B2:B21) -> 0.0875 | O21: =AVERAGE(C2:C21) -> 0.1 | P21: =AVERAGE(B2:B21) -> 0.0875 | Q21: =AVERAGE(C2:C21) -> 0.1 | R21: =AVERAGE(B2:B21) -> 0.0875 | S21: =AVERAGE(C2:C21) -> 0.1 | T21: =AVERAGE(B2:B21) -> 0.0875 | U21: =AVERAGE(C2:C21) -> 0.1
A22: 21 | B22: 0 | C22: 0 | D22: =IF(A22>=$X$2,A22-$X$2+1,"") | E22: =IF(A22>=$X$3,A22-$X$3+1,"") | F22: =AVERAGE(B18:B22) -> 0.25 | G22: =AVERAGE(C18:C22) -> 0.05 | H22: =AVERAGE(B13:B22) -> 0.15 | I22: =AVERAGE(C13:C22) -> 0.075 | J22: =AVERAGE(B8:B22) -> 0.1 | K22: =AVERAGE(C8:C22) -> 0.1 | L22: =AVERAGE(B3:B22) -> 0.0875 | M22: =AVERAGE(C3:C22) -> 0.0875 | N22: =AVERAGE(B2:B22) -> 0.083333333 | O22: =AVERAGE(C2:C22) -> 0.095238095 | P22: =AVERAGE(B2:B22) -> 0.083333333 | Q22: =AVERAGE(C2:C22) -> 0.095238095 | R22: =AVERAGE(B2:B22) -> 0.083333333 | S22: =AVERAGE(C2:C22) -> 0.095238095 | T22: =AVERAGE(B2:B22) -> 0.083333333 | U22: =AVERAGE(C2:C22) -> 0.095238095
A23: 22 | B23: 0.25 | C23: 0.25 | D23: =IF(A23>=$X$2,A23-$X$2+1,"") | E23: =IF(A23>=$X$3,A23-$X$3+1,"") | F23: =AVERAGE(B19:B23) -> 0.2 | G23: =AVERAGE(C19:C23) -> 0.1 | H23: =AVERAGE(B14:B23) -> 0.175 | I23: =AVERAGE(C14:C23) -> 0.1 | J23: =AVERAGE(B9:B23) -> 0.11666667 | K23: =AVERAGE(C9:C23) -> 0.11666667 | L23: =AVERAGE(B4:B23) -> 0.1 | M23: =AVERAGE(C4:C23) -> 0.1 | N23: =AVERAGE(B2:B23) -> 0.090909091 | O23: =AVERAGE(C2:C23) -> 0.10227273 | P23: =AVERAGE(B2:B23) -> 0.090909091 | Q23: =AVERAGE(C2:C23) -> 0.10227273 | R23: =AVERAGE(B2:B23) -> 0.090909091 | S23: =AVERAGE(C2:C23) -> 0.10227273 | T23: =AVERAGE(B2:B23) -> 0.090909091 | U23: =AVERAGE(C2:C23) -> 0.10227273
A24: 23 | B24: 0 | C24: 0.25 | D24: =IF(A24>=$X$2,A24-$X$2+1,"") | E24: =IF(A24>=$X$3,A24-$X$3+1,"") | F24: =AVERAGE(B20:B24) -> 0.2 | G24: =AVERAGE(C20:C24) -> 0.1 | H24: =AVERAGE(B15:B24) -> 0.15 | I24: =AVERAGE(C15:C24) -> 0.125 | J24: =AVERAGE(B10:B24) -> 0.11666667 | K24: =AVERAGE(C10:C24) -> 0.083333333 | L24: =AVERAGE(B5:B24) -> 0.0875 | M24: =AVERAGE(C5:C24) -> 0.1125 | N24: =AVERAGE(B2:B24) -> 0.086956522 | O24: =AVERAGE(C2:C24) -> 0.10869565 | P24: =AVERAGE(B2:B24) -> 0.086956522 | Q24: =AVERAGE(C2:C24) -> 0.10869565 | R24: =AVERAGE(B2:B24) -> 0.086956522 | S24: =AVERAGE(C2:C24) -> 0.10869565 | T24: =AVERAGE(B2:B24) -> 0.086956522 | U24: =AVERAGE(C2:C24) -> 0.10869565
A25: 24 | B25: 0 | C25: 0 | D25: =IF(A25>=$X$2,A25-$X$2+1,"") | E25: =IF(A25>=$X$3,A25-$X$3+1,"") | F25: =AVERAGE(B21:B25) -> 0.15 | G25: =AVERAGE(C21:C25) -> 0.1 | H25: =AVERAGE(B16:B25) -> 0.15 | I25: =AVERAGE(C16:C25) -> 0.125 | J25: =AVERAGE(B11:B25) -> 0.11666667 | K25: =AVERAGE(C11:C25) -> 0.083333333 | L25: =AVERAGE(B6:B25) -> 0.0875 | M25: =AVERAGE(C6:C25) -> 0.1 | N25: =AVERAGE(B2:B25) -> 0.083333333 | O25: =AVERAGE(C2:C25) -> 0.10416667 | P25: =AVERAGE(B2:B25) -> 0.083333333 | Q25: =AVERAGE(C2:C25) -> 0.10416667 | R25: =AVERAGE(B2:B25) -> 0.083333333 | S25: =AVERAGE(C2:C25) -> 0.10416667 | T25: =AVERAGE(B2:B25) -> 0.083333333 | U25: =AVERAGE(C2:C25) -> 0.10416667
A26: 25 | B26: 0 | C26: 0 | D26: =IF(A26>=$X$2,A26-$X$2+1,"") | E26: =IF(A26>=$X$3,A26-$X$3+1,"") | F26: =AVERAGE(B22:B26) -> 0.05 | G26: =AVERAGE(C22:C26) -> 0.1 | H26: =AVERAGE(B17:B26) -> 0.15 | I26: =AVERAGE(C17:C26) -> 0.075 | J26: =AVERAGE(B12:B26) -> 0.11666667 | K26: =AVERAGE(C12:C26) -> 0.083333333 | L26: =AVERAGE(B7:B26) -> 0.0875 | M26: =AVERAGE(C7:C26) -> 0.1 | N26: =AVERAGE(B2:B26) -> 0.08 | O26: =AVERAGE(C2:C26) -> 0.1 | P26: =AVERAGE(B2:B26) -> 0.08 | Q26: =AVERAGE(C2:C26) -> 0.1 | R26: =AVERAGE(B2:B26) -> 0.08 | S26: =AVERAGE(C2:C26) -> 0.1 | T26: =AVERAGE(B2:B26) -> 0.08 | U26: =AVERAGE(C2:C26) -> 0.1
A27: 26 | B27: 0.25 | C27: 0 | D27: =IF(A27>=$X$2,A27-$X$2+1,"") | E27: =IF(A27>=$X$3,A27-$X$3+1,"") | F27: =AVERAGE(B23:B27) -> 0.1 | G27: =AVERAGE(C23:C27) -> 0.1 | H27: =AVERAGE(B18:B27) -> 0.175 | I27: =AVERAGE(C18:C27) -> 0.075 | J27: =AVERAGE(B13:B27) -> 0.13333333 | K27: =AVERAGE(C13:C27) -> 0.083333333 | L27: =AVERAGE(B8:B27) -> 0.1 | M27: =AVERAGE(C8:C27) -> 0.1 | N27: =AVERAGE(B3:B27) -> 0.09 | O27: =AVERAGE(C3:C27) -> 0.09 | P27: =AVERAGE(B2:B27) -> 0.086538462 | Q27: =AVERAGE(C2:C27) -> 0.096153846 | R27: =AVERAGE(B2:B27) -> 0.086538462 | S27: =AVERAGE(C2:C27) -> 0.096153846 | T27: =AVERAGE(B2:B27) -> 0.086538462 | U27: =AVERAGE(C2:C27) -> 0.096153846
A28: 27 | B28: 0 | C28: 0 | D28: =IF(A28>=$X$2,A28-$X$2+1,"") | E28: =IF(A28>=$X$3,A28-$X$3+1,"") | F28: =AVERAGE(B24:B28) -> 0.05 | G28: =AVERAGE(C24:C28) -> 0.05 | H28: =AVERAGE(B19:B28) -> 0.125 | I28: =AVERAGE(C19:C28) -> 0.075 | J28: =AVERAGE(B14:B28) -> 0.13333333 | K28: =AVERAGE(C14:C28) -> 0.083333333 | L28: =AVERAGE(B9:B28) -> 0.1 | M28: =AVERAGE(C9:C28) -> 0.1 | N28: =AVERAGE(B4:B28) -> 0.09 | O28: =AVERAGE(C4:C28) -> 0.09 | P28: =AVERAGE(B2:B28) -> 0.083333333 | Q28: =AVERAGE(C2:C28) -> 0.092592593 | R28: =AVERAGE(B2:B28) -> 0.083333333 | S28: =AVERAGE(C2:C28) -> 0.092592593 | T28: =AVERAGE(B2:B28) -> 0.083333333 | U28: =AVERAGE(C2:C28) -> 0.092592593
A29: 28 | B29: 0 | C29: 0 | D29: =IF(A29>=$X$2,A29-$X$2+1,"") | E29: =IF(A29>=$X$3,A29-$X$3+1,"") | F29: =AVERAGE(B25:B29) -> 0.05 | G29: =AVERAGE(C25:C29) -> 0 | H29: =AVERAGE(B20:B29) -> 0.125 | I29: =AVERAGE(C20:C29) -> 0.05 | J29: =AVERAGE(B15:B29) -> 0.11666667 | K29: =AVERAGE(C15:C29) -> 0.083333333 | L29: =AVERAGE(B10:B29) -> 0.1 | M29: =AVERAGE(C10:C29) -> 0.0625 | N29: =AVERAGE(B5:B29) -> 0.08 | O29: =AVERAGE(C5:C29) -> 0.09 | P29: =AVERAGE(B2:B29) -> 0.080357143 | Q29: =AVERAGE(C2:C29) -> 0.089285714 | R29: =AVERAGE(B2:B29) -> 0.080357143 | S29: =AVERAGE(C2:C29) -> 0.089285714 | T29: =AVERAGE(B2:B29) -> 0.080357143 | U29: =AVERAGE(C2:C29) -> 0.089285714
A30: 29 | B30: 0 | C30: 0 | D30: =IF(A30>=$X$2,A30-$X$2+1,"") | E30: =IF(A30>=$X$3,A30-$X$3+1,"") | F30: =AVERAGE(B26:B30) -> 0.05 | G30: =AVERAGE(C26:C30) -> 0 | H30: =AVERAGE(B21:B30) -> 0.1 | I30: =AVERAGE(C21:C30) -> 0.05 | J30: =AVERAGE(B16:B30) -> 0.11666667 | K30: =AVERAGE(C16:C30) -> 0.083333333 | L30: =AVERAGE(B11:B30) -> 0.1 | M30: =AVERAGE(C11:C30) -> 0.0625 | N30: =AVERAGE(B6:B30) -> 0.08 | O30: =AVERAGE(C6:C30) -> 0.08 | P30: =AVERAGE(B2:B30) -> 0.077586207 | Q30: =AVERAGE(C2:C30) -> 0.086206897 | R30: =AVERAGE(B2:B30) -> 0.077586207 | S30: =AVERAGE(C2:C30) -> 0.086206897 | T30: =AVERAGE(B2:B30) -> 0.077586207 | U30: =AVERAGE(C2:C30) -> 0.086206897
A31: 30 | B31: 0.25 | C31: 0 | D31: =IF(A31>=$X$2,A31-$X$2+1,"") | E31: =IF(A31>=$X$3,A31-$X$3+1,"") | F31: =AVERAGE(B27:B31) -> 0.1 | G31: =AVERAGE(C27:C31) -> 0 | H31: =AVERAGE(B22:B31) -> 0.075 | I31: =AVERAGE(C22:C31) -> 0.05 | J31: =AVERAGE(B17:B31) -> 0.13333333 | K31: =AVERAGE(C17:C31) -> 0.05 | L31: =AVERAGE(B12:B31) -> 0.1125 | M31: =AVERAGE(C12:C31) -> 0.0625 | N31: =AVERAGE(B7:B31) -> 0.09 | O31: =AVERAGE(C7:C31) -> 0.08 | P31: =AVERAGE(B2:B31) -> 0.083333333 | Q31: =AVERAGE(C2:C31) -> 0.083333333 | R31: =AVERAGE(B2:B31) -> 0.083333333 | S31: =AVERAGE(C2:C31) -> 0.083333333 | T31: =AVERAGE(B2:B31) -> 0.083333333 | U31: =AVERAGE(C2:C31) -> 0.083333333
A32: 31 | B32: 0 | C32: 0 | D32: =IF(A32>=$X$2,A32-$X$2+1,"") | E32: =IF(A32>=$X$3,A32-$X$3+1,"") | F32: =AVERAGE(B28:B32) -> 0.05 | G32: =AVERAGE(C28:C32) -> 0 | H32: =AVERAGE(B23:B32) -> 0.075 | I32: =AVERAGE(C23:C32) -> 0.05 | J32: =AVERAGE(B18:B32) -> 0.13333333 | K32: =AVERAGE(C18:C32) -> 0.05 | L32: =AVERAGE(B13:B32) -> 0.1125 | M32: =AVERAGE(C13:C32) -> 0.0625 | N32: =AVERAGE(B8:B32) -> 0.09 | O32: =AVERAGE(C8:C32) -> 0.08 | P32: =AVERAGE(B3:B32) -> 0.083333333 | Q32: =AVERAGE(C3:C32) -> 0.075 | R32: =AVERAGE(B2:B32) -> 0.080645161 | S32: =AVERAGE(C2:C32) -> 0.080645161 | T32: =AVERAGE(B2:B32) -> 0.080645161 | U32: =AVERAGE(C2:C32) -> 0.080645161
A33: 32 | B33: 0.25 | C33: 0 | D33: =IF(A33>=$X$2,A33-$X$2+1,"") | E33: =IF(A33>=$X$3,A33-$X$3+1,"") | F33: =AVERAGE(B29:B33) -> 0.1 | G33: =AVERAGE(C29:C33) -> 0 | H33: =AVERAGE(B24:B33) -> 0.075 | I33: =AVERAGE(C24:C33) -> 0.025 | J33: =AVERAGE(B19:B33) -> 0.11666667 | K33: =AVERAGE(C19:C33) -> 0.05 | L33: =AVERAGE(B14:B33) -> 0.125 | M33: =AVERAGE(C14:C33) -> 0.0625 | N33: =AVERAGE(B9:B33) -> 0.1 | O33: =AVERAGE(C9:C33) -> 0.08 | P33: =AVERAGE(B4:B33) -> 0.091666667 | Q33: =AVERAGE(C4:C33) -> 0.075 | R33: =AVERAGE(B2:B33) -> 0.0859375 | S33: =AVERAGE(C2:C33) -> 0.078125 | T33: =AVERAGE(B2:B33) -> 0.0859375 | U33: =AVERAGE(C2:C33) -> 0.078125
A34: 33 | B34: 0 | C34: 0 | D34: =IF(A34>=$X$2,A34-$X$2+1,"") | E34: =IF(A34>=$X$3,A34-$X$3+1,"") | F34: =AVERAGE(B30:B34) -> 0.1 | G34: =AVERAGE(C30:C34) -> 0 | H34: =AVERAGE(B25:B34) -> 0.075 | I34: =AVERAGE(C25:C34) -> 0 | J34: =AVERAGE(B20:B34) -> 0.11666667 | K34: =AVERAGE(C20:C34) -> 0.033333333 | L34: =AVERAGE(B15:B34) -> 0.1125 | M34: =AVERAGE(C15:C34) -> 0.0625 | N34: =AVERAGE(B10:B34) -> 0.1 | O34: =AVERAGE(C10:C34) -> 0.05 | P34: =AVERAGE(B5:B34) -> 0.083333333 | Q34: =AVERAGE(C5:C34) -> 0.075 | R34: =AVERAGE(B2:B34) -> 0.083333333 | S34: =AVERAGE(C2:C34) -> 0.075757576 | T34: =AVERAGE(B2:B34) -> 0.083333333 | U34: =AVERAGE(C2:C34) -> 0.075757576
A35: 34 | B35: 0 | C35: 0 | D35: =IF(A35>=$X$2,A35-$X$2+1,"") | E35: =IF(A35>=$X$3,A35-$X$3+1,"") | F35: =AVERAGE(B31:B35) -> 0.1 | G35: =AVERAGE(C31:C35) -> 0 | H35: =AVERAGE(B26:B35) -> 0.075 | I35: =AVERAGE(C26:C35) -> 0 | J35: =AVERAGE(B21:B35) -> 0.1 | K35: =AVERAGE(C21:C35) -> 0.033333333 | L35: =AVERAGE(B16:B35) -> 0.1125 | M35: =AVERAGE(C16:C35) -> 0.0625 | N35: =AVERAGE(B11:B35) -> 0.1 | O35: =AVERAGE(C11:C35) -> 0.05 | P35: =AVERAGE(B6:B35) -> 0.083333333 | Q35: =AVERAGE(C6:C35) -> 0.066666667 | R35: =AVERAGE(B2:B35) -> 0.080882353 | S35: =AVERAGE(C2:C35) -> 0.073529412 | T35: =AVERAGE(B2:B35) -> 0.080882353 | U35: =AVERAGE(C2:C35) -> 0.073529412
A36: 35 | B36: 0 | C36: 0.25 | D36: =IF(A36>=$X$2,A36-$X$2+1,"") | E36: =IF(A36>=$X$3,A36-$X$3+1,"") | F36: =AVERAGE(B32:B36) -> 0.05 | G36: =AVERAGE(C32:C36) -> 0.05 | H36: =AVERAGE(B27:B36) -> 0.075 | I36: =AVERAGE(C27:C36) -> 0.025 | J36: =AVERAGE(B22:B36) -> 0.066666667 | K36: =AVERAGE(C22:C36) -> 0.05 | L36: =AVERAGE(B17:B36) -> 0.1125 | M36: =AVERAGE(C17:C36) -> 0.05 | N36: =AVERAGE(B12:B36) -> 0.1 | O36: =AVERAGE(C12:C36) -> 0.06 | P36: =AVERAGE(B7:B36) -> 0.083333333 | Q36: =AVERAGE(C7:C36) -> 0.075 | R36: =AVERAGE(B2:B36) -> 0.078571429 | S36: =AVERAGE(C2:C36) -> 0.078571429 | T36: =AVERAGE(B2:B36) -> 0.078571429 | U36: =AVERAGE(C2:C36) -> 0.078571429
A37: 36 | B37: 0.25 | C37: 0 | D37: =IF(A37>=$X$2,A37-$X$2+1,"") | E37: =IF(A37>=$X$3,A37-$X$3+1,"") | F37: =AVERAGE(B33:B37) -> 0.1 | G37: =AVERAGE(C33:C37) -> 0.05 | H37: =AVERAGE(B28:B37) -> 0.075 | I37: =AVERAGE(C28:C37) -> 0.025 | J37: =AVERAGE(B23:B37) -> 0.083333333 | K37: =AVERAGE(C23:C37) -> 0.05 | L37: =AVERAGE(B18:B37) -> 0.125 | M37: =AVERAGE(C18:C37) -> 0.05 | N37: =AVERAGE(B13:B37) -> 0.11 | O37: =AVERAGE(C13:C37) -> 0.06 | P37: =AVERAGE(B8:B37) -> 0.091666667 | Q37: =AVERAGE(C8:C37) -> 0.075 | R37: =AVERAGE(B2:B37) -> 0.083333333 | S37: =AVERAGE(C2:C37) -> 0.076388889 | T37: =AVERAGE(B2:B37) -> 0.083333333 | U37: =AVERAGE(C2:C37) -> 0.076388889
A38: 37 | B38: 0 | C38: 0 | D38: =IF(A38>=$X$2,A38-$X$2+1,"") | E38: =IF(A38>=$X$3,A38-$X$3+1,"") | F38: =AVERAGE(B34:B38) -> 0.05 | G38: =AVERAGE(C34:C38) -> 0.05 | H38: =AVERAGE(B29:B38) -> 0.075 | I38: =AVERAGE(C29:C38) -> 0.025 | J38: =AVERAGE(B24:B38) -> 0.066666667 | K38: =AVERAGE(C24:C38) -> 0.033333333 | L38: =AVERAGE(B19:B38) -> 0.1 | M38: =AVERAGE(C19:C38) -> 0.05 | N38: =AVERAGE(B14:B38) -> 0.11 | O38: =AVERAGE(C14:C38) -> 0.06 | P38: =AVERAGE(B9:B38) -> 0.091666667 | Q38: =AVERAGE(C9:C38) -> 0.075 | R38: =AVERAGE(B2:B38) -> 0.081081081 | S38: =AVERAGE(C2:C38) -> 0.074324324 | T38: =AVERAGE(B2:B38) -> 0.081081081 | U38: =AVERAGE(C2:C38) -> 0.074324324
A39: 38 | B39: 0.25 | C39: 0 | D39: =IF(A39>=$X$2,A39-$X$2+1,"") | E39: =IF(A39>=$X$3,A39-$X$3+1,"") | F39: =AVERAGE(B35:B39) -> 0.1 | G39: =AVERAGE(C35:C39) -> 0.05 | H39: =AVERAGE(B30:B39) -> 0.1 | I39: =AVERAGE(C30:C39) -> 0.025 | J39: =AVERAGE(B25:B39) -> 0.083333333 | K39: =AVERAGE(C25:C39) -> 0.016666667 | L39: =AVERAGE(B20:B39) -> 0.1125 | M39: =AVERAGE(C20:C39) -> 0.0375 | N39: =AVERAGE(B15:B39) -> 0.11 | O39: =AVERAGE(C15:C39) -> 0.06 | P39: =AVERAGE(B10:B39) -> 0.1 | Q39: =AVERAGE(C10:C39) -> 0.05 | R39: =AVERAGE(B2:B39) -> 0.085526316 | S39: =AVERAGE(C2:C39) -> 0.072368421 | T39: =AVERAGE(B2:B39) -> 0.085526316 | U39: =AVERAGE(C2:C39) -> 0.072368421
A40: 39 | B40: 0 | C40: 0 | D40: =IF(A40>=$X$2,A40-$X$2+1,"") | E40: =IF(A40>=$X$3,A40-$X$3+1,"") | F40: =AVERAGE(B36:B40) -> 0.1 | G40: =AVERAGE(C36:C40) -> 0.05 | H40: =AVERAGE(B31:B40) -> 0.1 | I40: =AVERAGE(C31:C40) -> 0.025 | J40: =AVERAGE(B26:B40) -> 0.083333333 | K40: =AVERAGE(C26:C40) -> 0.016666667 | L40: =AVERAGE(B21:B40) -> 0.1 | M40: =AVERAGE(C21:C40) -> 0.0375 | N40: =AVERAGE(B16:B40) -> 0.11 | O40: =AVERAGE(C16:C40) -> 0.06 | P40: =AVERAGE(B11:B40) -> 0.1 | Q40: =AVERAGE(C11:C40) -> 0.05 | R40: =AVERAGE(B2:B40) -> 0.083333333 | S40: =AVERAGE(C2:C40) -> 0.070512821 | T40: =AVERAGE(B2:B40) -> 0.083333333 | U40: =AVERAGE(C2:C40) -> 0.070512821
...

Sheet 采样效率 0920
A1: MA Window | B1: Target SR | C1: Clean Steps | D1: DVCA Steps | E1: Fewer Steps | F1: Clean Episodes | G1: DVCA Episodes | H1: Episode Reduction
A2: 5 | B2: 0.85 | C2: =_xlfn.MINIFS('π0.5 RLT 0920'!$A$2:$A$801,'π0.5 RLT 0920'!$F$2:$F$801,">="&B2,'π0.5 RLT 0920'!$A$2:$A$801,">="&145)-145+1 -> 18 | D2: =_xlfn.MINIFS('π0.5 RLT 0920'!$A$2:$A$801,'π0.5 RLT 0920'!$G$2:$G$801,">="&B2,'π0.5 RLT 0920'!$A$2:$A$801,">="&146)-146+1 -> 20 | E2: =1-D2/C2 -> -0.11111111 | F2: =C2*'π0.5 RLT 0920'!$X$4 -> 72 | G2: =D2*'π0.5 RLT 0920'!$X$4 -> 80 | H2: =1-G2/F2 -> -0.11111111
A3: 5 | B3: 0.9 | C3: =_xlfn.MINIFS('π0.5 RLT 0920'!$A$2:$A$801,'π0.5 RLT 0920'!$F$2:$F$801,">="&B3,'π0.5 RLT 0920'!$A$2:$A$801,">="&145)-145+1 -> 19 | D3: =_xlfn.MINIFS('π0.5 RLT 0920'!$A$2:$A$801,'π0.5 RLT 0920'!$G$2:$G$801,">="&B3,'π0.5 RLT 0920'!$A$2:$A$801,">="&146)-146+1 -> 20 | E3: =1-D3/C3 -> -0.052631579 | F3: =C3*'π0.5 RLT 0920'!$X$4 -> 76 | G3: =D3*'π0.5 RLT 0920'!$X$4 -> 80 | H3: =1-G3/F3 -> -0.052631579
A4: 5 | B4: 0.95 | C4: =_xlfn.MINIFS('π0.5 RLT 0920'!$A$2:$A$801,'π0.5 RLT 0920'!$F$2:$F$801,">="&B4,'π0.5 RLT 0920'!$A$2:$A$801,">="&145)-145+1 -> 21 | D4: =_xlfn.MINIFS('π0.5 RLT 0920'!$A$2:$A$801,'π0.5 RLT 0920'!$G$2:$G$801,">="&B4,'π0.5 RLT 0920'!$A$2:$A$801,">="&146)-146+1 -> 23 | E4: =1-D4/C4 -> -0.095238095 | F4: =C4*'π0.5 RLT 0920'!$X$4 -> 84 | G4: =D4*'π0.5 RLT 0920'!$X$4 -> 92 | H4: =1-G4/F4 -> -0.095238095
A5: 10 | B5: 0.85 | C5: =_xlfn.MINIFS('π0.5 RLT 0920'!$A$2:$A$801,'π0.5 RLT 0920'!$H$2:$H$801,">="&B5,'π0.5 RLT 0920'!$A$2:$A$801,">="&145)-145+1 -> 21 | D5: =_xlfn.MINIFS('π0.5 RLT 0920'!$A$2:$A$801,'π0.5 RLT 0920'!$I$2:$I$801,">="&B5,'π0.5 RLT 0920'!$A$2:$A$801,">="&146)-146+1 -> 24 | E5: =1-D5/C5 -> -0.14285714 | F5: =C5*'π0.5 RLT 0920'!$X$4 -> 84 | G5: =D5*'π0.5 RLT 0920'!$X$4 -> 96 | H5: =1-G5/F5 -> -0.14285714
A6: 10 | B6: 0.9 | C6: =_xlfn.MINIFS('π0.5 RLT 0920'!$A$2:$A$801,'π0.5 RLT 0920'!$H$2:$H$801,">="&B6,'π0.5 RLT 0920'!$A$2:$A$801,">="&145)-145+1 -> 70 | D6: =_xlfn.MINIFS('π0.5 RLT 0920'!$A$2:$A$801,'π0.5 RLT 0920'!$I$2:$I$801,">="&B6,'π0.5 RLT 0920'!$A$2:$A$801,">="&146)-146+1 -> 25 | E6: =1-D6/C6 -> 0.64285714 | F6: =C6*'π0.5 RLT 0920'!$X$4 -> 280 | G6: =D6*'π0.5 RLT 0920'!$X$4 -> 100 | H6: =1-G6/F6 -> 0.64285714
A7: 10 | B7: 0.95 | C7: =_xlfn.MINIFS('π0.5 RLT 0920'!$A$2:$A$801,'π0.5 RLT 0920'!$H$2:$H$801,">="&B7,'π0.5 RLT 0920'!$A$2:$A$801,">="&145)-145+1 -> 84 | D7: =_xlfn.MINIFS('π0.5 RLT 0920'!$A$2:$A$801,'π0.5 RLT 0920'!$I$2:$I$801,">="&B7,'π0.5 RLT 0920'!$A$2:$A$801,">="&146)-146+1 -> 26 | E7: =1-D7/C7 -> 0.69047619 | F7: =C7*'π0.5 RLT 0920'!$X$4 -> 336 | G7: =D7*'π0.5 RLT 0920'!$X$4 -> 104 | H7: =1-G7/F7 -> 0.69047619
A8: 15 | B8: 0.85 | C8: =_xlfn.MINIFS('π0.5 RLT 0920'!$A$2:$A$801,'π0.5 RLT 0920'!$J$2:$J$801,">="&B8,'π0.5 RLT 0920'!$A$2:$A$801,">="&145)-145+1 -> 31 | D8: =_xlfn.MINIFS('π0.5 RLT 0920'!$A$2:$A$801,'π0.5 RLT 0920'!$K$2:$K$801,">="&B8,'π0.5 RLT 0920'!$A$2:$A$801,">="&146)-146+1 -> 27 | E8: =1-D8/C8 -> 0.12903226 | F8: =C8*'π0.5 RLT 0920'!$X$4 -> 124 | G8: =D8*'π0.5 RLT 0920'!$X$4 -> 108 | H8: =1-G8/F8 -> 0.12903226
A9: 15 | B9: 0.9 | C9: =_xlfn.MINIFS('π0.5 RLT 0920'!$A$2:$A$801,'π0.5 RLT 0920'!$J$2:$J$801,">="&B9,'π0.5 RLT 0920'!$A$2:$A$801,">="&145)-145+1 -> 77 | D9: =_xlfn.MINIFS('π0.5 RLT 0920'!$A$2:$A$801,'π0.5 RLT 0920'!$K$2:$K$801,">="&B9,'π0.5 RLT 0920'!$A$2:$A$801,">="&146)-146+1 -> 29 | E9: =1-D9/C9 -> 0.62337662 | F9: =C9*'π0.5 RLT 0920'!$X$4 -> 308 | G9: =D9*'π0.5 RLT 0920'!$X$4 -> 116 | H9: =1-G9/F9 -> 0.62337662
A10: 15 | B10: 0.95 | C10: =_xlfn.MINIFS('π0.5 RLT 0920'!$A$2:$A$801,'π0.5 RLT 0920'!$J$2:$J$801,">="&B10,'π0.5 RLT 0920'!$A$2:$A$801,">="&145)-145+1 -> 103 | D10: =_xlfn.MINIFS('π0.5 RLT 0920'!$A$2:$A$801,'π0.5 RLT 0920'!$K$2:$K$801,">="&B10,'π0.5 RLT 0920'!$A$2:$A$801,">="&146)-146+1 -> 30 | E10: =1-D10/C10 -> 0.70873786 | F10: =C10*'π0.5 RLT 0920'!$X$4 -> 412 | G10: =D10*'π0.5 RLT 0920'!$X$4 -> 120 | H10: =1-G10/F10 -> 0.70873786
A11: 20 | B11: 0.85 | C11: =_xlfn.MINIFS('π0.5 RLT 0920'!$A$2:$A$801,'π0.5 RLT 0920'!$L$2:$L$801,">="&B11,'π0.5 RLT 0920'!$A$2:$A$801,">="&145)-145+1 -> 70 | D11: =_xlfn.MINIFS('π0.5 RLT 0920'!$A$2:$A$801,'π0.5 RLT 0920'!$M$2:$M$801,">="&B11,'π0.5 RLT 0920'!$A$2:$A$801,">="&146)-146+1 -> 31 | E11: =1-D11/C11 -> 0.55714286 | F11: =C11*'π0.5 RLT 0920'!$X$4 -> 280 | G11: =D11*'π0.5 RLT 0920'!$X$4 -> 124 | H11: =1-G11/F11 -> 0.55714286
A12: 20 | B12: 0.9 | C12: =_xlfn.MINIFS('π0.5 RLT 0920'!$A$2:$A$801,'π0.5 RLT 0920'!$L$2:$L$801,">="&B12,'π0.5 RLT 0920'!$A$2:$A$801,">="&145)-145+1 -> 80 | D12: =_xlfn.MINIFS('π0.5 RLT 0920'!$A$2:$A$801,'π0.5 RLT 0920'!$M$2:$M$801,">="&B12,'π0.5 RLT 0920'!$A$2:$A$801,">="&146)-146+1 -> 32 | E12: =1-D12/C12 -> 0.6 | F12: =C12*'π0.5 RLT 0920'!$X$4 -> 320 | G12: =D12*'π0.5 RLT 0920'!$X$4 -> 128 | H12: =1-G12/F12 -> 0.6
A13: 20 | B13: 0.95 | C13: =_xlfn.MINIFS('π0.5 RLT 0920'!$A$2:$A$801,'π0.5 RLT 0920'!$L$2:$L$801,">="&B13,'π0.5 RLT 0920'!$A$2:$A$801,">="&145)-145+1 -> 150 | D13: =_xlfn.MINIFS('π0.5 RLT 0920'!$A$2:$A$801,'π0.5 RLT 0920'!$M$2:$M$801,">="&B13,'π0.5 RLT 0920'!$A$2:$A$801,">="&146)-146+1 -> 35 | E13: =1-D13/C13 -> 0.76666667 | F13: =C13*'π0.5 RLT 0920'!$X$4 -> 600 | G13: =D13*'π0.5 RLT 0920'!$X$4 -> 140 | H13: =1-G13/F13 -> 0.76666667
A14: 25 | B14: 0.85 | C14: =_xlfn.MINIFS('π0.5 RLT 0920'!$A$2:$A$801,'π0.5 RLT 0920'!$N$2:$N$801,">="&B14,'π0.5 RLT 0920'!$A$2:$A$801,">="&145)-145+1 -> 41 | D14: =_xlfn.MINIFS('π0.5 RLT 0920'!$A$2:$A$801,'π0.5 RLT 0920'!$O$2:$O$801,">="&B14,'π0.5 RLT 0920'!$A$2:$A$801,">="&146)-146+1 -> 34 | E14: =1-D14/C14 -> 0.17073171 | F14: =C14*'π0.5 RLT 0920'!$X$4 -> 164 | G14: =D14*'π0.5 RLT 0920'!$X$4 -> 136 | H14: =1-G14/F14 -> 0.17073171
A15: 25 | B15: 0.9 | C15: =_xlfn.MINIFS('π0.5 RLT 0920'!$A$2:$A$801,'π0.5 RLT 0920'!$N$2:$N$801,">="&B15,'π0.5 RLT 0920'!$A$2:$A$801,">="&145)-145+1 -> 82 | D15: =_xlfn.MINIFS('π0.5 RLT 0920'!$A$2:$A$801,'π0.5 RLT 0920'!$O$2:$O$801,">="&B15,'π0.5 RLT 0920'!$A$2:$A$801,">="&146)-146+1 -> 36 | E15: =1-D15/C15 -> 0.56097561 | F15: =C15*'π0.5 RLT 0920'!$X$4 -> 328 | G15: =D15*'π0.5 RLT 0920'!$X$4 -> 144 | H15: =1-G15/F15 -> 0.56097561
A16: 25 | B16: 0.95 | C16: =_xlfn.MINIFS('π0.5 RLT 0920'!$A$2:$A$801,'π0.5 RLT 0920'!$N$2:$N$801,">="&B16,'π0.5 RLT 0920'!$A$2:$A$801,">="&145)-145+1 -> 151 | D16: =_xlfn.MINIFS('π0.5 RLT 0920'!$A$2:$A$801,'π0.5 RLT 0920'!$O$2:$O$801,">="&B16,'π0.5 RLT 0920'!$A$2:$A$801,">="&146)-146+1 -> 40 | E16: =1-D16/C16 -> 0.73509934 | F16: =C16*'π0.5 RLT 0920'!$X$4 -> 604 | G16: =D16*'π0.5 RLT 0920'!$X$4 -> 160 | H16: =1-G16/F16 -> 0.73509934
A17: 30 | B17: 0.85 | C17: =_xlfn.MINIFS('π0.5 RLT 0920'!$A$2:$A$801,'π0.5 RLT 0920'!$P$2:$P$801,">="&B17,'π0.5 RLT 0920'!$A$2:$A$801,">="&145)-145+1 -> 79 | D17: =_xlfn.MINIFS('π0.5 RLT 0920'!$A$2:$A$801,'π0.5 RLT 0920'!$Q$2:$Q$801,">="&B17,'π0.5 RLT 0920'!$A$2:$A$801,">="&146)-146+1 -> 39 | E17: =1-D17/C17 -> 0.50632911 | F17: =C17*'π0.5 RLT 0920'!$X$4 -> 316 | G17: =D17*'π0.5 RLT 0920'!$X$4 -> 156 | H17: =1-G17/F17 -> 0.50632911
A18: 30 | B18: 0.9 | C18: =_xlfn.MINIFS('π0.5 RLT 0920'!$A$2:$A$801,'π0.5 RLT 0920'!$P$2:$P$801,">="&B18,'π0.5 RLT 0920'!$A$2:$A$801,">="&145)-145+1 -> 94 | D18: =_xlfn.MINIFS('π0.5 RLT 0920'!$A$2:$A$801,'π0.5 RLT 0920'!$Q$2:$Q$801,">="&B18,'π0.5 RLT 0920'!$A$2:$A$801,">="&146)-146+1 -> 41 | E18: =1-D18/C18 -> 0.56382979 | F18: =C18*'π0.5 RLT 0920'!$X$4 -> 376 | G18: =D18*'π0.5 RLT 0920'!$X$4 -> 164 | H18: =1-G18/F18 -> 0.56382979
A19: 30 | B19: 0.95 | C19: =_xlfn.MINIFS('π0.5 RLT 0920'!$A$2:$A$801,'π0.5 RLT 0920'!$P$2:$P$801,">="&B19,'π0.5 RLT 0920'!$A$2:$A$801,">="&145)-145+1 -> 156 | D19: =_xlfn.MINIFS('π0.5 RLT 0920'!$A$2:$A$801,'π0.5 RLT 0920'!$Q$2:$Q$801,">="&B19,'π0.5 RLT 0920'!$A$2:$A$801,">="&146)-146+1 -> 45 | E19: =1-D19/C19 -> 0.71153846 | F19: =C19*'π0.5 RLT 0920'!$X$4 -> 624 | G19: =D19*'π0.5 RLT 0920'!$X$4 -> 180 | H19: =1-G19/F19 -> 0.71153846
A20: 40 | B20: 0.85 | C20: =_xlfn.MINIFS('π0.5 RLT 0920'!$A$2:$A$801,'π0.5 RLT 0920'!$R$2:$R$801,">="&B20,'π0.5 RLT 0920'!$A$2:$A$801,">="&145)-145+1 -> 83 | D20: =_xlfn.MINIFS('π0.5 RLT 0920'!$A$2:$A$801,'π0.5 RLT 0920'!$S$2:$S$801,">="&B20,'π0.5 RLT 0920'!$A$2:$A$801,">="&146)-146+1 -> 46 | E20: =1-D20/C20 -> 0.44578313 | F20: =C20*'π0.5 RLT 0920'!$X$4 -> 332 | G20: =D20*'π0.5 RLT 0920'!$X$4 -> 184 | H20: =1-G20/F20 -> 0.44578313
A21: 40 | B21: 0.9 | C21: =_xlfn.MINIFS('π0.5 RLT 0920'!$A$2:$A$801,'π0.5 RLT 0920'!$R$2:$R$801,">="&B21,'π0.5 RLT 0920'!$A$2:$A$801,">="&145)-145+1 -> 99 | D21: =_xlfn.MINIFS('π0.5 RLT 0920'!$A$2:$A$801,'π0.5 RLT 0920'!$S$2:$S$801,">="&B21,'π0.5 RLT 0920'!$A$2:$A$801,">="&146)-146+1 -> 50 | E21: =1-D21/C21 -> 0.49494949 | F21: =C21*'π0.5 RLT 0920'!$X$4 -> 396 | G21: =D21*'π0.5 RLT 0920'!$X$4 -> 200 | H21: =1-G21/F21 -> 0.49494949
A22: 40 | B22: 0.95 | C22: =_xlfn.MINIFS('π0.5 RLT 0920'!$A$2:$A$801,'π0.5 RLT 0920'!$R$2:$R$801,">="&B22,'π0.5 RLT 0920'!$A$2:$A$801,">="&145)-145+1 -> 176 | D22: =_xlfn.MINIFS('π0.5 RLT 0920'!$A$2:$A$801,'π0.5 RLT 0920'!$S$2:$S$801,">="&B22,'π0.5 RLT 0920'!$A$2:$A$801,">="&146)-146+1 -> 55 | E22: =1-D22/C22 -> 0.6875 | F22: =C22*'π0.5 RLT 0920'!$X$4 -> 704 | G22: =D22*'π0.5 RLT 0920'!$X$4 -> 220 | H22: =1-G22/F22 -> 0.6875
A23: 50 | B23: 0.85 | C23: =_xlfn.MINIFS('π0.5 RLT 0920'!$A$2:$A$801,'π0.5 RLT 0920'!$T$2:$T$801,">="&B23,'π0.5 RLT 0920'!$A$2:$A$801,">="&145)-145+1 -> 83 | D23: =_xlfn.MINIFS('π0.5 RLT 0920'!$A$2:$A$801,'π0.5 RLT 0920'!$U$2:$U$801,">="&B23,'π0.5 RLT 0920'!$A$2:$A$801,">="&146)-146+1 -> 53 | E23: =1-D23/C23 -> 0.36144578 | F23: =C23*'π0.5 RLT 0920'!$X$4 -> 332 | G23: =D23*'π0.5 RLT 0920'!$X$4 -> 212 | H23: =1-G23/F23 -> 0.36144578
A24: 50 | B24: 0.9 | C24: =_xlfn.MINIFS('π0.5 RLT 0920'!$A$2:$A$801,'π0.5 RLT 0920'!$T$2:$T$801,">="&B24,'π0.5 RLT 0920'!$A$2:$A$801,">="&145)-145+1 -> 110 | D24: =_xlfn.MINIFS('π0.5 RLT 0920'!$A$2:$A$801,'π0.5 RLT 0920'!$U$2:$U$801,">="&B24,'π0.5 RLT 0920'!$A$2:$A$801,">="&146)-146+1 -> 59 | E24: =1-D24/C24 -> 0.46363636 | F24: =C24*'π0.5 RLT 0920'!$X$4 -> 440 | G24: =D24*'π0.5 RLT 0920'!$X$4 -> 236 | H24: =1-G24/F24 -> 0.46363636
A25: 50 | B25: 0.95 | C25: =_xlfn.MINIFS('π0.5 RLT 0920'!$A$2:$A$801,'π0.5 RLT 0920'!$T$2:$T$801,">="&B25,'π0.5 RLT 0920'!$A$2:$A$801,">="&145)-145+1 -> 185 | D25: =_xlfn.MINIFS('π0.5 RLT 0920'!$A$2:$A$801,'π0.5 RLT 0920'!$U$2:$U$801,">="&B25,'π0.5 RLT 0920'!$A$2:$A$801,">="&146)-146+1 -> 65 | E25: =1-D25/C25 -> 0.64864865 | F25: =C25*'π0.5 RLT 0920'!$X$4 -> 740 | G25: =D25*'π0.5 RLT 0920'!$X$4 -> 260 | H25: =1-G25/F25 -> 0.64864865
A28: First threshold crossing after student participation; student rounds are numbered from 1.

Sheet 消融实验 0921
A1: Run | B1: τ | C1: Dropout | D1: Annealing | E1: Student start | F1: Last round | G1: Records | H1: Source run
A2: t05 | B2: 0.5 | C2: 0 | D2: 0 | E2: 145 | F2: 500 | G2: 500 | H2: /data/chenyiteng/results/rlinf-rlt/pi05-rlt-t05-notricks-clean4-800-phys4-20260920-v1
A3: t1 | B3: 1 | C3: 0 | D3: 0 | E3: 146 | F3: 499 | G3: 499 | H3: /data/chenyiteng/results/rlinf-rlt/pi05-rlt-t1-notricks-clean4-800-phys5-20260920-v1
A4: t15 | B4: 1.5 | C4: 0 | D4: 0 | E4: 145 | F4: 515 | G4: 515 | H4: /data/chenyiteng/results/rlinf-rlt/pi05-rlt-t15-notricks-clean4-800-phys6-20260920-v1
A5: t2 | B5: 2 | C5: 0 | D5: 0 | E5: 145 | F5: 355 | G5: 355 | H5: /data/chenyiteng/results/rlinf-rlt/pi05-rlt-t2-notricks-clean4-800-phys4-20260920-v1
A6: t25 | B6: 2.5 | C6: 0 | D6: 0 | E6: 145 | F6: 348 | G6: 348 | H6: /data/chenyiteng/results/rlinf-rlt/pi05-rlt-t25-notricks-clean4-800-phys5-20260920-v1
A7: t3 | B7: 3 | C7: 0 | D7: 0 | E7: 146 | F7: 508 | G7: 508 | H7: /data/chenyiteng/results/rlinf-rlt/pi05-rlt-t3-notricks-clean4-800-phys7-20260920-v1
A8: t25-combo | B8: 2.5 | C8: 1 | D8: 1 | E8: 146 | F8: 800 | G8: 800 | H8: /data/chenyiteng/results/rlinf-rlt/pi05-rlt-combo-clean4-800-20260919-v1
A9: t25-anneal | B9: 2.5 | C9: 0 | D9: 1 | E9: 146 | F9: 440 | G9: 440 | H9: /data/chenyiteng/results/rlinf-rlt/pi05-rlt-t25-anneal-clean4-800-phys7-20260920-v1
A10: t25-drop | B10: 2.5 | C10: 1 | D10: 0 | E10: 146 | F10: 429 | G10: 429 | H10: /data/chenyiteng/results/rlinf-rlt/pi05-rlt-t25-drop-clean4-800-phys6-20260920-v1
A13: Metric | B13: env/success_once
A14: Smoothing | B14: Trailing mean on full history; min_periods=1; then crop from first student participation
A15: Display | B15: τ: first 200 student steps; tricks: first 200 student steps
A16: Archive | B16: pi05-rlt4-bottle-family-20260921.zip
A19: Panel | B19: Window | C19: Run | D19: Peak SR | E19: First peak step
A20: tau | B20: 5 | C20: t05 | D20: =MAX('消融平滑 0921'!D146:D345) -> 1 | E20: =MATCH(MAX('消融平滑 0921'!D146:D345),'消融平滑 0921'!D146:D345,0) -> 53
A21: tau | B21: 5 | C21: t1 | D21: =MAX('消融平滑 0921'!D647:D846) -> 1 | E21: =MATCH(MAX('消融平滑 0921'!D647:D846),'消融平滑 0921'!D647:D846,0) -> 29
A22: tau | B22: 5 | C22: t15 | D22: =MAX('消融平滑 0921'!D1145:D1344) -> 1 | E22: =MATCH(MAX('消融平滑 0921'!D1145:D1344),'消融平滑 0921'!D1145:D1344,0) -> 34
A23: tau | B23: 5 | C23: t2 | D23: =MAX('消融平滑 0921'!D1660:D1859) -> 1 | E23: =MATCH(MAX('消融平滑 0921'!D1660:D1859),'消融平滑 0921'!D1660:D1859,0) -> 45
A24: tau | B24: 5 | C24: t25 | D24: =MAX('消融平滑 0921'!D2015:D2214) -> 1 | E24: =MATCH(MAX('消融平滑 0921'!D2015:D2214),'消融平滑 0921'!D2015:D2214,0) -> 79
A25: tau | B25: 5 | C25: t3 | D25: =MAX('消融平滑 0921'!D2364:D2563) -> 1 | E25: =MATCH(MAX('消融平滑 0921'!D2364:D2563),'消融平滑 0921'!D2364:D2563,0) -> 52
A26: tau | B26: 10 | C26: t05 | D26: =MAX('消融平滑 0921'!E146:E345) -> 1 | E26: =MATCH(MAX('消融平滑 0921'!E146:E345),'消融平滑 0921'!E146:E345,0) -> 58
A27: tau | B27: 10 | C27: t1 | D27: =MAX('消融平滑 0921'!E647:E846) -> 1 | E27: =MATCH(MAX('消融平滑 0921'!E647:E846),'消融平滑 0921'!E647:E846,0) -> 127
A28: tau | B28: 10 | C28: t15 | D28: =MAX('消融平滑 0921'!E1145:E1344) -> 1 | E28: =MATCH(MAX('消融平滑 0921'!E1145:E1344),'消融平滑 0921'!E1145:E1344,0) -> 49
A29: tau | B29: 10 | C29: t2 | D29: =MAX('消融平滑 0921'!E1660:E1859) -> 1 | E29: =MATCH(MAX('消融平滑 0921'!E1660:E1859),'消融平滑 0921'!E1660:E1859,0) -> 50
A30: tau | B30: 10 | C30: t25 | D30: =MAX('消融平滑 0921'!E2015:E2214) -> 1 | E30: =MATCH(MAX('消融平滑 0921'!E2015:E2214),'消融平滑 0921'!E2015:E2214,0) -> 170
A31: tau | B31: 10 | C31: t3 | D31: =MAX('消融平滑 0921'!E2364:E2563) -> 1 | E31: =MATCH(MAX('消融平滑 0921'!E2364:E2563),'消融平滑 0921'!E2364:E2563,0) -> 65
A32: tau | B32: 15 | C32: t05 | D32: =MAX('消融平滑 0921'!F146:F345) -> 1 | E32: =MATCH(MAX('消融平滑 0921'!F146:F345),'消融平滑 0921'!F146:F345,0) -> 63
A33: tau | B33: 15 | C33: t1 | D33: =MAX('消融平滑 0921'!F647:F846) -> 0.98333333 | E33: =MATCH(MAX('消融平滑 0921'!F647:F846),'消融平滑 0921'!F647:F846,0) -> 132
A34: tau | B34: 15 | C34: t15 | D34: =MAX('消融平滑 0921'!F1145:F1344) -> 1 | E34: =MATCH(MAX('消融平滑 0921'!F1145:F1344),'消融平滑 0921'!F1145:F1344,0) -> 54
A35: tau | B35: 15 | C35: t2 | D35: =MAX('消融平滑 0921'!F1660:F1859) -> 1 | E35: =MATCH(MAX('消融平滑 0921'!F1660:F1859),'消融平滑 0921'!F1660:F1859,0) -> 76
A36: tau | B36: 15 | C36: t25 | D36: =MAX('消融平滑 0921'!F2015:F2214) -> 1 | E36: =MATCH(MAX('消融平滑 0921'!F2015:F2214),'消融平滑 0921'!F2015:F2214,0) -> 175
A37: tau | B37: 15 | C37: t3 | D37: =MAX('消融平滑 0921'!F2364:F2563) -> 0.98333333 | E37: =MATCH(MAX('消融平滑 0921'!F2364:F2563),'消融平滑 0921'!F2364:F2563,0) -> 69
A38: tau | B38: 20 | C38: t05 | D38: =MAX('消融平滑 0921'!G146:G345) -> 1 | E38: =MATCH(MAX('消融平滑 0921'!G146:G345),'消融平滑 0921'!G146:G345,0) -> 68
A39: tau | B39: 20 | C39: t1 | D39: =MAX('消融平滑 0921'!G647:G846) -> 0.9875 | E39: =MATCH(MAX('消融平滑 0921'!G647:G846),'消融平滑 0921'!G647:G846,0) -> 199
A40: tau | B40: 20 | C40: t15 | D40: =MAX('消融平滑 0921'!G1145:G1344) -> 1 | E40: =MATCH(MAX('消融平滑 0921'!G1145:G1344),'消融平滑 0921'!G1145:G1344,0) -> 59
A41: tau | B41: 20 | C41: t2 | D41: =MAX('消融平滑 0921'!G1660:G1859) -> 1 | E41: =MATCH(MAX('消融平滑 0921'!G1660:G1859),'消融平滑 0921'!G1660:G1859,0) -> 81
A42: tau | B42: 20 | C42: t25 | D42: =MAX('消融平滑 0921'!G2015:G2214) -> 0.975 | E42: =MATCH(MAX('消融平滑 0921'!G2015:G2214),'消融平滑 0921'!G2015:G2214,0) -> 169
A43: tau | B43: 20 | C43: t3 | D43: =MAX('消融平滑 0921'!G2364:G2563) -> 0.9875 | E43: =MATCH(MAX('消融平滑 0921'!G2364:G2563),'消融平滑 0921'!G2364:G2563,0) -> 75
A44: tau | B44: 25 | C44: t05 | D44: =MAX('消融平滑 0921'!H146:H345) -> 0.99 | E44: =MATCH(MAX('消融平滑 0921'!H146:H345),'消融平滑 0921'!H146:H345,0) -> 73
...

Sheet 消融原始 0921
A1: Run | B1: Global round | C1: Raw step | D1: Success rate | E1: Actor switch rate | F1: Wall time
A2: t05 | B2: 1 | C2: 0 | D2: 0 | E2: 0 | F2: 1.7899168e+09
A3: t05 | B3: 2 | C3: 1 | D3: 0 | E3: 0 | F3: 1.7899169e+09
A4: t05 | B4: 3 | C4: 2 | D4: 0 | E4: 0 | F4: 1.789917e+09
A5: t05 | B5: 4 | C5: 3 | D5: 0 | E5: 0 | F5: 1.789917e+09
A6: t05 | B6: 5 | C6: 4 | D6: 0.25 | E6: 0 | F6: 1.7899171e+09
A7: t05 | B7: 6 | C7: 5 | D7: 0 | E7: 0 | F7: 1.7899172e+09
A8: t05 | B8: 7 | C8: 6 | D8: 0 | E8: 0 | F8: 1.7899173e+09
A9: t05 | B9: 8 | C9: 7 | D9: 0 | E9: 0 | F9: 1.7899174e+09
A10: t05 | B10: 9 | C10: 8 | D10: 0 | E10: 0 | F10: 1.7899175e+09
A11: t05 | B11: 10 | C11: 9 | D11: 0 | E11: 0 | F11: 1.7899176e+09
A12: t05 | B12: 11 | C12: 10 | D12: 0 | E12: 0 | F12: 1.7899176e+09
A13: t05 | B13: 12 | C13: 11 | D13: 0 | E13: 0 | F13: 1.7899177e+09
... A500: t05 | B500: 499 | C500: 498 | D500: 1 | E500: 1 | F500: 1.7899627e+09
A501: t05 | B501: 500 | C501: 499 | D501: 1 | F501: 1.7899631e+09
A502: t1 | B502: 1 | C502: 0 | D502: 0 | E502: 0 | F502: 1.7899168e+09
A503: t1 | B503: 2 | C503: 1 | D503: 0 | E503: 0 | F503: 1.7899169e+09
A504: t1 | B504: 3 | C504: 2 | D504: 0.5 | E504: 0 | F504: 1.789917e+09
A505: t1 | B505: 4 | C505: 3 | D505: 0.25 | E505: 0 | F505: 1.789917e+09
A506: t1 | B506: 5 | C506: 4 | D506: 0 | E506: 0 | F506: 1.7899171e+09
A507: t1 | B507: 6 | C507: 5 | D507: 0 | E507: 0 | F507: 1.7899172e+09
A508: t1 | B508: 7 | C508: 6 | D508: 0 | E508: 0 | F508: 1.7899173e+09
A509: t1 | B509: 8 | C509: 7 | D509: 0.25 | E509: 0 | F509: 1.7899174e+09
A510: t1 | B510: 9 | C510: 8 | D510: 0 | E510: 0 | F510: 1.7899175e+09
A511: t1 | B511: 10 | C511: 9 | D511: 0.25 | E511: 0 | F511: 1.7899176e+09
A512: t1 | B512: 11 | C512: 10 | D512: 0 | E512: 0 | F512: 1.7899176e+09
A513: t1 | B513: 12 | C513: 11 | D513: 0 | E513: 0 | F513: 1.7899177e+09
... A4395: t25-drop | B4395: 429 | C4395: 428 | D4395: 1 | E4395: 1 | F4395: 1.7899166e+09

Sheet 消融平滑 0921
A1: Run | B1: Global round | C1: Student step | D1: MA5 | E1: MA10 | F1: MA15 | G1: MA20 | H1: MA25 | I1: MA30 | J1: MA40 | K1: MA50
A2: t05 | B2: 1 | C2: ='消融原始 0921'!B2-'消融实验 0921'!$E$2+1 -> -143 | D2: =AVERAGE('消融原始 0921'!D2:D2) -> 0 | E2: =AVERAGE('消融原始 0921'!D2:D2) -> 0 | F2: =AVERAGE('消融原始 0921'!D2:D2) -> 0 | G2: =AVERAGE('消融原始 0921'!D2:D2) -> 0 | H2: =AVERAGE('消融原始 0921'!D2:D2) -> 0 | I2: =AVERAGE('消融原始 0921'!D2:D2) -> 0 | J2: =AVERAGE('消融原始 0921'!D2:D2) -> 0 | K2: =AVERAGE('消融原始 0921'!D2:D2) -> 0
A3: t05 | B3: 2 | C3: ='消融原始 0921'!B3-'消融实验 0921'!$E$2+1 -> -142 | D3: =AVERAGE('消融原始 0921'!D2:D3) -> 0 | E3: =AVERAGE('消融原始 0921'!D2:D3) -> 0 | F3: =AVERAGE('消融原始 0921'!D2:D3) -> 0 | G3: =AVERAGE('消融原始 0921'!D2:D3) -> 0 | H3: =AVERAGE('消融原始 0921'!D2:D3) -> 0 | I3: =AVERAGE('消融原始 0921'!D2:D3) -> 0 | J3: =AVERAGE('消融原始 0921'!D2:D3) -> 0 | K3: =AVERAGE('消融原始 0921'!D2:D3) -> 0
A4: t05 | B4: 3 | C4: ='消融原始 0921'!B4-'消融实验 0921'!$E$2+1 -> -141 | D4: =AVERAGE('消融原始 0921'!D2:D4) -> 0 | E4: =AVERAGE('消融原始 0921'!D2:D4) -> 0 | F4: =AVERAGE('消融原始 0921'!D2:D4) -> 0 | G4: =AVERAGE('消融原始 0921'!D2:D4) -> 0 | H4: =AVERAGE('消融原始 0921'!D2:D4) -> 0 | I4: =AVERAGE('消融原始 0921'!D2:D4) -> 0 | J4: =AVERAGE('消融原始 0921'!D2:D4) -> 0 | K4: =AVERAGE('消融原始 0921'!D2:D4) -> 0
A5: t05 | B5: 4 | C5: ='消融原始 0921'!B5-'消融实验 0921'!$E$2+1 -> -140 | D5: =AVERAGE('消融原始 0921'!D2:D5) -> 0 | E5: =AVERAGE('消融原始 0921'!D2:D5) -> 0 | F5: =AVERAGE('消融原始 0921'!D2:D5) -> 0 | G5: =AVERAGE('消融原始 0921'!D2:D5) -> 0 | H5: =AVERAGE('消融原始 0921'!D2:D5) -> 0 | I5: =AVERAGE('消融原始 0921'!D2:D5) -> 0 | J5: =AVERAGE('消融原始 0921'!D2:D5) -> 0 | K5: =AVERAGE('消融原始 0921'!D2:D5) -> 0
A6: t05 | B6: 5 | C6: ='消融原始 0921'!B6-'消融实验 0921'!$E$2+1 -> -139 | D6: =AVERAGE('消融原始 0921'!D2:D6) -> 0.05 | E6: =AVERAGE('消融原始 0921'!D2:D6) -> 0.05 | F6: =AVERAGE('消融原始 0921'!D2:D6) -> 0.05 | G6: =AVERAGE('消融原始 0921'!D2:D6) -> 0.05 | H6: =AVERAGE('消融原始 0921'!D2:D6) -> 0.05 | I6: =AVERAGE('消融原始 0921'!D2:D6) -> 0.05 | J6: =AVERAGE('消融原始 0921'!D2:D6) -> 0.05 | K6: =AVERAGE('消融原始 0921'!D2:D6) -> 0.05
A7: t05 | B7: 6 | C7: ='消融原始 0921'!B7-'消融实验 0921'!$E$2+1 -> -138 | D7: =AVERAGE('消融原始 0921'!D3:D7) -> 0.05 | E7: =AVERAGE('消融原始 0921'!D2:D7) -> 0.041666667 | F7: =AVERAGE('消融原始 0921'!D2:D7) -> 0.041666667 | G7: =AVERAGE('消融原始 0921'!D2:D7) -> 0.041666667 | H7: =AVERAGE('消融原始 0921'!D2:D7) -> 0.041666667 | I7: =AVERAGE('消融原始 0921'!D2:D7) -> 0.041666667 | J7: =AVERAGE('消融原始 0921'!D2:D7) -> 0.041666667 | K7: =AVERAGE('消融原始 0921'!D2:D7) -> 0.041666667
A8: t05 | B8: 7 | C8: ='消融原始 0921'!B8-'消融实验 0921'!$E$2+1 -> -137 | D8: =AVERAGE('消融原始 0921'!D4:D8) -> 0.05 | E8: =AVERAGE('消融原始 0921'!D2:D8) -> 0.035714286 | F8: =AVERAGE('消融原始 0921'!D2:D8) -> 0.035714286 | G8: =AVERAGE('消融原始 0921'!D2:D8) -> 0.035714286 | H8: =AVERAGE('消融原始 0921'!D2:D8) -> 0.035714286 | I8: =AVERAGE('消融原始 0921'!D2:D8) -> 0.035714286 | J8: =AVERAGE('消融原始 0921'!D2:D8) -> 0.035714286 | K8: =AVERAGE('消融原始 0921'!D2:D8) -> 0.035714286
A9: t05 | B9: 8 | C9: ='消融原始 0921'!B9-'消融实验 0921'!$E$2+1 -> -136 | D9: =AVERAGE('消融原始 0921'!D5:D9) -> 0.05 | E9: =AVERAGE('消融原始 0921'!D2:D9) -> 0.03125 | F9: =AVERAGE('消融原始 0921'!D2:D9) -> 0.03125 | G9: =AVERAGE('消融原始 0921'!D2:D9) -> 0.03125 | H9: =AVERAGE('消融原始 0921'!D2:D9) -> 0.03125 | I9: =AVERAGE('消融原始 0921'!D2:D9) -> 0.03125 | J9: =AVERAGE('消融原始 0921'!D2:D9) -> 0.03125 | K9: =AVERAGE('消融原始 0921'!D2:D9) -> 0.03125
A10: t05 | B10: 9 | C10: ='消融原始 0921'!B10-'消融实验 0921'!$E$2+1 -> -135 | D10: =AVERAGE('消融原始 0921'!D6:D10) -> 0.05 | E10: =AVERAGE('消融原始 0921'!D2:D10) -> 0.027777778 | F10: =AVERAGE('消融原始 0921'!D2:D10) -> 0.027777778 | G10: =AVERAGE('消融原始 0921'!D2:D10) -> 0.027777778 | H10: =AVERAGE('消融原始 0921'!D2:D10) -> 0.027777778 | I10: =AVERAGE('消融原始 0921'!D2:D10) -> 0.027777778 | J10: =AVERAGE('消融原始 0921'!D2:D10) -> 0.027777778 | K10: =AVERAGE('消融原始 0921'!D2:D10) -> 0.027777778
A11: t05 | B11: 10 | C11: ='消融原始 0921'!B11-'消融实验 0921'!$E$2+1 -> -134 | D11: =AVERAGE('消融原始 0921'!D7:D11) -> 0 | E11: =AVERAGE('消融原始 0921'!D2:D11) -> 0.025 | F11: =AVERAGE('消融原始 0921'!D2:D11) -> 0.025 | G11: =AVERAGE('消融原始 0921'!D2:D11) -> 0.025 | H11: =AVERAGE('消融原始 0921'!D2:D11) -> 0.025 | I11: =AVERAGE('消融原始 0921'!D2:D11) -> 0.025 | J11: =AVERAGE('消融原始 0921'!D2:D11) -> 0.025 | K11: =AVERAGE('消融原始 0921'!D2:D11) -> 0.025
A12: t05 | B12: 11 | C12: ='消融原始 0921'!B12-'消融实验 0921'!$E$2+1 -> -133 | D12: =AVERAGE('消融原始 0921'!D8:D12) -> 0 | E12: =AVERAGE('消融原始 0921'!D3:D12) -> 0.025 | F12: =AVERAGE('消融原始 0921'!D2:D12) -> 0.022727273 | G12: =AVERAGE('消融原始 0921'!D2:D12) -> 0.022727273 | H12: =AVERAGE('消融原始 0921'!D2:D12) -> 0.022727273 | I12: =AVERAGE('消融原始 0921'!D2:D12) -> 0.022727273 | J12: =AVERAGE('消融原始 0921'!D2:D12) -> 0.022727273 | K12: =AVERAGE('消融原始 0921'!D2:D12) -> 0.022727273
